Workbook

Sheet Sheet1
B1: No | C1: Type | D1: Alpha Helix | E1: Trihelix | F1: Betashets | G1: Betaturns | H1: Disorder | I1: 1465 | J1: 1452 | K1: 1440 | L1: 1424 | M1: 1405 | N1: 1390 | O1: 1375 | P1: 1346 | Q1: 1284 | R1: 1260 | S1: 1243 | T1: 1234 | U1: 1203 | V1: 1081 | W1: 1064 | X1: 1050 | Y1: 1033 | Z1: 1022 | AA1: 1012 | AB1: 1012 cm−1 | AC1: 1022 cm−1 | AD1: 1033 cm−1 | AE1: 1050 cm−1 | AF1: 1064 cm−1 | AG1: 1081 cm−1 | AH1: 1203 cm−1 | AI1: 1234 cm−1 | AJ1: 1243 cm−1 | AK1: 1260 cm−1 | AL1: 1284 cm−1 | AM1: 1346 cm−1 | AN1: 1375 cm−1 | AO1: 1390 cm−1 | AP1: 1405 cm−1 | AQ1: 1424 cm−1 | AR1: 1440 cm−1 | AS1: 1452 cm−1 | AT1: 1465 cm−1 | AU1: Alpha-like helix | AV1: Beta-sheets | AW1: Beta-turns | AX1: Triple helix | AY1: Unordered | AZ1: 1012 cm−1 | BA1: 1022 cm−1 | BB1: 1033 cm−1 | BC1: 1050 cm−1 | BD1: 1064 cm−1 | BE1: 1081 cm−1 | BF1: 1203 cm−1 | BG1: 1234 cm−1 | BH1: 1243 cm−1 | BI1: 1260 cm−1 | BJ1: 1284 cm−1 | BK1: 1346 cm−1 | BL1: 1375 cm−1 | BM1: 1390 cm−1 | BN1: 1405 cm−1 | BO1: 1424 cm−1 | BP1: 1440 cm−1 | BQ1: 1452 cm−1 | BR1: 1465 cm−1 | BS1: Alpha-like helix | BT1: Beta-sheets | BU1: Beta-turns | BV1: Triple helix | BW1: Unordered | BX1: Mean | BY1: SD | BZ1: Trihelix | CA1: Betashets | CB1: Betaturns | CC1: Disorder | CD1: 1465 | CE1: 1452 | CF1: 1440 | CG1: 1424 | CH1: 1405 | CI1: 1390 | CJ1: 1375 | CK1: 1346 | CL1: 1284 | CM1: 1260 | CN1: 1243 | CO1: 1234 | CP1: 1203 | CQ1: 1081 | CR1: 1064 | CS1: 1050 | CT1: 1033 | CU1: 1022 | CV1: 1012 | CW1: Alpha Helix | CX1: Trihelix | CY1: Betashets | CZ1: Betaturns
B2: 1 | C2: 1 | D2: =RAND() -> 0.51976591 | E2: =RAND() -> 0.36928566 | F2: =RAND() -> 0.99996431 | G2: =RAND() -> 0.91652262 | H2: =RAND() -> 0.13658165 | I2: =RAND() -> 0.65762929 | J2: =RAND() -> 0.18893823 | K2: =RAND() -> 0.51555593 | ... AA2: =RAND() -> 0.34011012 | AB2: =D2*Sheet2!C$14/_xlfn.STDEV.S(D$2:D$31) -> 1.0429723 | AC2: =E2*Sheet2!D$14/_xlfn.STDEV.S(E$2:E$31) -> 2.7084817 | AD2: =F2*Sheet2!E$14/_xlfn.STDEV.S(F$2:F$31) -> 4.6686831 | AE2: =G2*Sheet2!F$14/_xlfn.STDEV.S(G$2:G$31) -> 7.4734689 | AF2: =H2*Sheet2!G$14/_xlfn.STDEV.S(H$2:H$31) -> 0.8771382 | AG2: =I2*Sheet2!H$14/_xlfn.STDEV.S(I$2:I$31) -> 7.0889674 | AH2: =J2*Sheet2!I$14/_xlfn.STDEV.S(J$2:J$31) -> 0.46053187 | AI2: =K2*Sheet2!J$14/_xlfn.STDEV.S(K$2:K$31) -> 1.5144359 | ... AY2: =AA2*Sheet2!Z$14/_xlfn.STDEV.S(AA$2:AA$31) -> 0.81582412 | AZ2: =AB2-AVERAGE(AB$2:AB$31)+Sheet2!C$13 -> 3.3011902 | BA2: =AC2-AVERAGE(AC$2:AC$31)+Sheet2!D$13 -> 5.7130162 | BB2: =AD2-AVERAGE(AD$2:AD$31)+Sheet2!E$13 -> 20.343037 | BC2: =AE2-AVERAGE(AE$2:AE$31)+Sheet2!F$13 -> 24.449684 | BD2: =AF2-AVERAGE(AF$2:AF$31)+Sheet2!G$13 -> 16.964021 | BE2: =AG2-AVERAGE(AG$2:AG$31)+Sheet2!H$13 -> 30.709782 | BF2: =AH2-AVERAGE(AH$2:AH$31)+Sheet2!I$13 -> 11.245717 | BG2: =AI2-AVERAGE(AI$2:AI$31)+Sheet2!J$13 -> 19.755805 | ... BW2: =AY2-AVERAGE(AY$2:AY$31)+Sheet2!Z$13 -> 7.7010138 | BZ2: =BA2-AVERAGE(BA$2:BA$31)+Sheet2!AB$13 -> -1.0511954 | CA2: =BB2-AVERAGE(BB$2:BB$31)+Sheet2!AC$13 -> 1.7190871 | CB2: =BC2-AVERAGE(BC$2:BC$31)+Sheet2!AD$13 -> 3.3588231 | CC2: =BD2-AVERAGE(BD$2:BD$31)+Sheet2!AE$13 -> -2.1977621
B3: 2 | C3: 1 | D3: =RAND() -> 0.54440082 | E3: =RAND() -> 0.14673193 | F3: =RAND() -> 0.93129605 | G3: =RAND() -> 0.72853666 | H3: =RAND() -> 0.87370154 | I3: =RAND() -> 0.87164669 | J3: =RAND() -> 0.35163872 | K3: =RAND() -> 0.97564789 | ... AA3: =RAND() -> 0.63925898 | AB3: =D3*Sheet2!C$14/_xlfn.STDEV.S(D$2:D$31) -> 1.0924052 | AC3: =E3*Sheet2!D$14/_xlfn.STDEV.S(E$2:E$31) -> 1.0761879 | AD3: =F3*Sheet2!E$14/_xlfn.STDEV.S(F$2:F$31) -> 4.3480813 | AE3: =G3*Sheet2!F$14/_xlfn.STDEV.S(G$2:G$31) -> 5.940602 | AF3: =H3*Sheet2!G$14/_xlfn.STDEV.S(H$2:H$31) -> 5.6109808 | AG3: =I3*Sheet2!H$14/_xlfn.STDEV.S(I$2:I$31) -> 9.3959851 | AH3: =J3*Sheet2!I$14/_xlfn.STDEV.S(J$2:J$31) -> 0.85710996 | AI3: =K3*Sheet2!J$14/_xlfn.STDEV.S(K$2:K$31) -> 2.8659475 | ... AY3: =AA3*Sheet2!Z$14/_xlfn.STDEV.S(AA$2:AA$31) -> 1.5333943 | AZ3: =AB3-AVERAGE(AB$2:AB$31)+Sheet2!C$13 -> 3.3506231 | BA3: =AC3-AVERAGE(AC$2:AC$31)+Sheet2!D$13 -> 4.0807223 | BB3: =AD3-AVERAGE(AD$2:AD$31)+Sheet2!E$13 -> 20.022435 | BC3: =AE3-AVERAGE(AE$2:AE$31)+Sheet2!F$13 -> 22.916817 | BD3: =AF3-AVERAGE(AF$2:AF$31)+Sheet2!G$13 -> 21.697863 | BE3: =AG3-AVERAGE(AG$2:AG$31)+Sheet2!H$13 -> 33.0168 | BF3: =AH3-AVERAGE(AH$2:AH$31)+Sheet2!I$13 -> 11.642295 | BG3: =AI3-AVERAGE(AI$2:AI$31)+Sheet2!J$13 -> 21.107316 | ... BW3: =AY3-AVERAGE(AY$2:AY$31)+Sheet2!Z$13 -> 8.418584 | BZ3: =BA3-AVERAGE(BA$2:BA$31)+Sheet2!AB$13 -> -2.6834892 | CA3: =BB3-AVERAGE(BB$2:BB$31)+Sheet2!AC$13 -> 1.3984853 | CB3: =BC3-AVERAGE(BC$2:BC$31)+Sheet2!AD$13 -> 1.8259562 | CC3: =BD3-AVERAGE(BD$2:BD$31)+Sheet2!AE$13 -> 2.5360805
B4: 3 | C4: 1 | D4: =RAND() -> 0.56081508 | E4: =RAND() -> 0.42809182 | F4: =RAND() -> 0.91026564 | G4: =RAND() -> 0.36069347 | H4: =RAND() -> 0.38432348 | I4: =RAND() -> 0.90001697 | J4: =RAND() -> 0.34318456 | K4: =RAND() -> 0.4505698 | ... AA4: =RAND() -> 0.79466693 | AB4: =D4*Sheet2!C$14/_xlfn.STDEV.S(D$2:D$31) -> 1.1253424 | AC4: =E4*Sheet2!D$14/_xlfn.STDEV.S(E$2:E$31) -> 3.1397884 | AD4: =F4*Sheet2!E$14/_xlfn.STDEV.S(F$2:F$31) -> 4.2498935 | AE4: =G4*Sheet2!F$14/_xlfn.STDEV.S(G$2:G$31) -> 2.941151 | AF4: =H4*Sheet2!G$14/_xlfn.STDEV.S(H$2:H$31) -> 2.468156 | AG4: =I4*Sheet2!H$14/_xlfn.STDEV.S(I$2:I$31) -> 9.7018048 | AH4: =J4*Sheet2!I$14/_xlfn.STDEV.S(J$2:J$31) -> 0.83650318 | AI4: =K4*Sheet2!J$14/_xlfn.STDEV.S(K$2:K$31) -> 1.3235404 | ... AY4: =AA4*Sheet2!Z$14/_xlfn.STDEV.S(AA$2:AA$31) -> 1.9061722 | AZ4: =AB4-AVERAGE(AB$2:AB$31)+Sheet2!C$13 -> 3.3835602 | BA4: =AC4-AVERAGE(AC$2:AC$31)+Sheet2!D$13 -> 6.1443229 | BB4: =AD4-AVERAGE(AD$2:AD$31)+Sheet2!E$13 -> 19.924247 | BC4: =AE4-AVERAGE(AE$2:AE$31)+Sheet2!F$13 -> 19.917366 | BD4: =AF4-AVERAGE(AF$2:AF$31)+Sheet2!G$13 -> 18.555039 | BE4: =AG4-AVERAGE(AG$2:AG$31)+Sheet2!H$13 -> 33.32262 | BF4: =AH4-AVERAGE(AH$2:AH$31)+Sheet2!I$13 -> 11.621689 | BG4: =AI4-AVERAGE(AI$2:AI$31)+Sheet2!J$13 -> 19.564909 | ... BW4: =AY4-AVERAGE(AY$2:AY$31)+Sheet2!Z$13 -> 8.7913619 | BZ4: =BA4-AVERAGE(BA$2:BA$31)+Sheet2!AB$13 -> -0.61988858 | CA4: =BB4-AVERAGE(BB$2:BB$31)+Sheet2!AC$13 -> 1.3002974 | CB4: =BC4-AVERAGE(BC$2:BC$31)+Sheet2!AD$13 -> -1.1734948 | CC4: =BD4-AVERAGE(BD$2:BD$31)+Sheet2!AE$13 -> -0.60674431
B5: 4 | C5: 1 | D5: =RAND() -> 0.82584004 | E5: =RAND() -> 0.77280685 | F5: =RAND() -> 0.55465604 | G5: =RAND() -> 0.52230931 | H5: =RAND() -> 0.61021605 | I5: =RAND() -> 0.4069365 | J5: =RAND() -> 0.78121222 | K5: =RAND() -> 0.92561858 | ... AA5: =RAND() -> 0.21113392 | AB5: =D5*Sheet2!C$14/_xlfn.STDEV.S(D$2:D$31) -> 1.6571466 | AC5: =E5*Sheet2!D$14/_xlfn.STDEV.S(E$2:E$31) -> 5.6680597 | AD5: =F5*Sheet2!E$14/_xlfn.STDEV.S(F$2:F$31) -> 2.5896057 | AE5: =G5*Sheet2!F$14/_xlfn.STDEV.S(G$2:G$31) -> 4.2589919 | AF5: =H5*Sheet2!G$14/_xlfn.STDEV.S(H$2:H$31) -> 3.918856 | AG5: =I5*Sheet2!H$14/_xlfn.STDEV.S(I$2:I$31) -> 4.3866044 | AH5: =J5*Sheet2!I$14/_xlfn.STDEV.S(J$2:J$31) -> 1.9041838 | AI5: =K5*Sheet2!J$14/_xlfn.STDEV.S(K$2:K$31) -> 2.7189873 | ... AY5: =AA5*Sheet2!Z$14/_xlfn.STDEV.S(AA$2:AA$31) -> 0.50644817 | AZ5: =AB5-AVERAGE(AB$2:AB$31)+Sheet2!C$13 -> 3.9153645 | BA5: =AC5-AVERAGE(AC$2:AC$31)+Sheet2!D$13 -> 8.6725942 | BB5: =AD5-AVERAGE(AD$2:AD$31)+Sheet2!E$13 -> 18.263959 | BC5: =AE5-AVERAGE(AE$2:AE$31)+Sheet2!F$13 -> 21.235207 | BD5: =AF5-AVERAGE(AF$2:AF$31)+Sheet2!G$13 -> 20.005739 | BE5: =AG5-AVERAGE(AG$2:AG$31)+Sheet2!H$13 -> 28.007419 | BF5: =AH5-AVERAGE(AH$2:AH$31)+Sheet2!I$13 -> 12.689369 | BG5: =AI5-AVERAGE(AI$2:AI$31)+Sheet2!J$13 -> 20.960356 | ... BW5: =AY5-AVERAGE(AY$2:AY$31)+Sheet2!Z$13 -> 7.3916379 | BZ5: =BA5-AVERAGE(BA$2:BA$31)+Sheet2!AB$13 -> 1.9083827 | CA5: =BB5-AVERAGE(BB$2:BB$31)+Sheet2!AC$13 -> -0.35999035 | CB5: =BC5-AVERAGE(BC$2:BC$31)+Sheet2!AD$13 -> 0.14434607 | CC5: =BD5-AVERAGE(BD$2:BD$31)+Sheet2!AE$13 -> 0.84395572
B6: 5 | C6: 1 | D6: =RAND() -> 0.33767065 | E6: =RAND() -> 0.85874984 | F6: =RAND() -> 0.78858701 | G6: =RAND() -> 0.1320552 | H6: =RAND() -> 0.36393335 | I6: =RAND() -> 0.46190209 | J6: =RAND() -> 0.15294845 | K6: =RAND() -> 0.75810347 | ... AA6: =RAND() -> 0.7847786 | AB6: =D6*Sheet2!C$14/_xlfn.STDEV.S(D$2:D$31) -> 0.67757649 | AC6: =E6*Sheet2!D$14/_xlfn.STDEV.S(E$2:E$31) -> 6.2983984 | AD6: =F6*Sheet2!E$14/_xlfn.STDEV.S(F$2:F$31) -> 3.6817942 | AE6: =G6*Sheet2!F$14/_xlfn.STDEV.S(G$2:G$31) -> 1.0767988 | AF6: =H6*Sheet2!G$14/_xlfn.STDEV.S(H$2:H$31) -> 2.337209 | AG6: =I6*Sheet2!H$14/_xlfn.STDEV.S(I$2:I$31) -> 4.9791104 | AH6: =J6*Sheet2!I$14/_xlfn.STDEV.S(J$2:J$31) -> 0.37280776 | AI6: =K6*Sheet2!J$14/_xlfn.STDEV.S(K$2:K$31) -> 2.2269148 | ... AY6: =AA6*Sheet2!Z$14/_xlfn.STDEV.S(AA$2:AA$31) -> 1.882453 | AZ6: =AB6-AVERAGE(AB$2:AB$31)+Sheet2!C$13 -> 2.9357943 | BA6: =AC6-AVERAGE(AC$2:AC$31)+Sheet2!D$13 -> 9.3029329 | BB6: =AD6-AVERAGE(AD$2:AD$31)+Sheet2!E$13 -> 19.356148 | BC6: =AE6-AVERAGE(AE$2:AE$31)+Sheet2!F$13 -> 18.053014 | BD6: =AF6-AVERAGE(AF$2:AF$31)+Sheet2!G$13 -> 18.424092 | BE6: =AG6-AVERAGE(AG$2:AG$31)+Sheet2!H$13 -> 28.599925 | BF6: =AH6-AVERAGE(AH$2:AH$31)+Sheet2!I$13 -> 11.157993 | BG6: =AI6-AVERAGE(AI$2:AI$31)+Sheet2!J$13 -> 20.468284 | ... BW6: =AY6-AVERAGE(AY$2:AY$31)+Sheet2!Z$13 -> 8.7676427 | BZ6: =BA6-AVERAGE(BA$2:BA$31)+Sheet2!AB$13 -> 2.5387213 | CA6: =BB6-AVERAGE(BB$2:BB$31)+Sheet2!AC$13 -> 0.73219823 | CB6: =BC6-AVERAGE(BC$2:BC$31)+Sheet2!AD$13 -> -3.037847 | CC6: =BD6-AVERAGE(BD$2:BD$31)+Sheet2!AE$13 -> -0.73769134
B7: 6 | C7: 1 | D7: =RAND() -> 0.1590516 | E7: =RAND() -> 0.087883012 | F7: =RAND() -> 0.48826426 | G7: =RAND() -> 0.18842197 | H7: =RAND() -> 0.57878223 | I7: =RAND() -> 0.43520954 | J7: =RAND() -> 0.3404211 | K7: =RAND() -> 0.87833877 | ... AA7: =RAND() -> 0.11674374 | AB7: =D7*Sheet2!C$14/_xlfn.STDEV.S(D$2:D$31) -> 0.31915602 | AC7: =E7*Sheet2!D$14/_xlfn.STDEV.S(E$2:E$31) -> 0.64456748 | AD7: =F7*Sheet2!E$14/_xlfn.STDEV.S(F$2:F$31) -> 2.2796325 | AE7: =G7*Sheet2!F$14/_xlfn.STDEV.S(G$2:G$31) -> 1.5364223 | AF7: =H7*Sheet2!G$14/_xlfn.STDEV.S(H$2:H$31) -> 3.7169855 | AG7: =I7*Sheet2!H$14/_xlfn.STDEV.S(I$2:I$31) -> 4.691376 | AH7: =J7*Sheet2!I$14/_xlfn.STDEV.S(J$2:J$31) -> 0.82976732 | AI7: =K7*Sheet2!J$14/_xlfn.STDEV.S(K$2:K$31) -> 2.5801037 | ... AY7: =AA7*Sheet2!Z$14/_xlfn.STDEV.S(AA$2:AA$31) -> 0.28003389 | AZ7: =AB7-AVERAGE(AB$2:AB$31)+Sheet2!C$13 -> 2.5773738 | BA7: =AC7-AVERAGE(AC$2:AC$31)+Sheet2!D$13 -> 3.649102 | BB7: =AD7-AVERAGE(AD$2:AD$31)+Sheet2!E$13 -> 17.953986 | BC7: =AE7-AVERAGE(AE$2:AE$31)+Sheet2!F$13 -> 18.512638 | BD7: =AF7-AVERAGE(AF$2:AF$31)+Sheet2!G$13 -> 19.803868 | BE7: =AG7-AVERAGE(AG$2:AG$31)+Sheet2!H$13 -> 28.312191 | BF7: =AH7-AVERAGE(AH$2:AH$31)+Sheet2!I$13 -> 11.614953 | BG7: =AI7-AVERAGE(AI$2:AI$31)+Sheet2!J$13 -> 20.821473 | ... BW7: =AY7-AVERAGE(AY$2:AY$31)+Sheet2!Z$13 -> 7.1652236 | BZ7: =BA7-AVERAGE(BA$2:BA$31)+Sheet2!AB$13 -> -3.1151096 | CA7: =BB7-AVERAGE(BB$2:BB$31)+Sheet2!AC$13 -> -0.66996356 | CB7: =BC7-AVERAGE(BC$2:BC$31)+Sheet2!AD$13 -> -2.5782235 | CC7: =BD7-AVERAGE(BD$2:BD$31)+Sheet2!AE$13 -> 0.64208521
B8: 7 | C8: 1 | D8: =RAND() -> 0.73628978 | E8: =RAND() -> 0.35007133 | F8: =RAND() -> 0.92826693 | G8: =RAND() -> 0.33451872 | H8: =RAND() -> 0.012869384 | I8: =RAND() -> 0.11762915 | J8: =RAND() -> 0.039866063 | K8: =RAND() -> 0.10524593 | ... AA8: =RAND() -> 0.16231666 | AB8: =D8*Sheet2!C$14/_xlfn.STDEV.S(D$2:D$31) -> 1.4774534 | AC8: =E8*Sheet2!D$14/_xlfn.STDEV.S(E$2:E$31) -> 2.5675565 | AD8: =F8*Sheet2!E$14/_xlfn.STDEV.S(F$2:F$31) -> 4.3339388 | AE8: =G8*Sheet2!F$14/_xlfn.STDEV.S(G$2:G$31) -> 2.727718 | AF8: =H8*Sheet2!G$14/_xlfn.STDEV.S(H$2:H$31) -> 0.082648209 | AG8: =I8*Sheet2!H$14/_xlfn.STDEV.S(I$2:I$31) -> 1.2679928 | AH8: =J8*Sheet2!I$14/_xlfn.STDEV.S(J$2:J$31) -> 0.09717246 | AI8: =K8*Sheet2!J$14/_xlfn.STDEV.S(K$2:K$31) -> 0.30915797 | ... AY8: =AA8*Sheet2!Z$14/_xlfn.STDEV.S(AA$2:AA$31) -> 0.38934991 | AZ8: =AB8-AVERAGE(AB$2:AB$31)+Sheet2!C$13 -> 3.7356712 | BA8: =AC8-AVERAGE(AC$2:AC$31)+Sheet2!D$13 -> 5.572091 | BB8: =AD8-AVERAGE(AD$2:AD$31)+Sheet2!E$13 -> 20.008292 | BC8: =AE8-AVERAGE(AE$2:AE$31)+Sheet2!F$13 -> 19.703933 | BD8: =AF8-AVERAGE(AF$2:AF$31)+Sheet2!G$13 -> 16.169531 | BE8: =AG8-AVERAGE(AG$2:AG$31)+Sheet2!H$13 -> 24.888808 | BF8: =AH8-AVERAGE(AH$2:AH$31)+Sheet2!I$13 -> 10.882358 | BG8: =AI8-AVERAGE(AI$2:AI$31)+Sheet2!J$13 -> 18.550527 | ... BW8: =AY8-AVERAGE(AY$2:AY$31)+Sheet2!Z$13 -> 7.2745396 | BZ8: =BA8-AVERAGE(BA$2:BA$31)+Sheet2!AB$13 -> -1.1921206 | CA8: =BB8-AVERAGE(BB$2:BB$31)+Sheet2!AC$13 -> 1.3843428 | CB8: =BC8-AVERAGE(BC$2:BC$31)+Sheet2!AD$13 -> -1.3869278 | CC8: =BD8-AVERAGE(BD$2:BD$31)+Sheet2!AE$13 -> -2.9922521
B9: 8 | C9: 1 | D9: =RAND() -> 0.4589572 | E9: =RAND() -> 0.51822131 | F9: =RAND() -> 0.73337104 | G9: =RAND() -> 0.87656506 | H9: =RAND() -> 0.84565902 | I9: =RAND() -> 0.87078458 | J9: =RAND() -> 0.81592661 | K9: =RAND() -> 0.41562655 | ... AA9: =RAND() -> 0.92175448 | AB9: =D9*Sheet2!C$14/_xlfn.STDEV.S(D$2:D$31) -> 0.92095242 | AC9: =E9*Sheet2!D$14/_xlfn.STDEV.S(E$2:E$31) -> 3.8008324 | AD9: =F9*Sheet2!E$14/_xlfn.STDEV.S(F$2:F$31) -> 3.4239992 | AE9: =G9*Sheet2!F$14/_xlfn.STDEV.S(G$2:G$31) -> 7.1476487 | AF9: =H9*Sheet2!G$14/_xlfn.STDEV.S(H$2:H$31) -> 5.4308895 | AG9: =I9*Sheet2!H$14/_xlfn.STDEV.S(I$2:I$31) -> 9.3866919 | AH9: =J9*Sheet2!I$14/_xlfn.STDEV.S(J$2:J$31) -> 1.9887992 | AI9: =K9*Sheet2!J$14/_xlfn.STDEV.S(K$2:K$31) -> 1.2208952 | ... AY9: =AA9*Sheet2!Z$14/_xlfn.STDEV.S(AA$2:AA$31) -> 2.2110178 | AZ9: =AB9-AVERAGE(AB$2:AB$31)+Sheet2!C$13 -> 3.1791702 | BA9: =AC9-AVERAGE(AC$2:AC$31)+Sheet2!D$13 -> 6.8053669 | BB9: =AD9-AVERAGE(AD$2:AD$31)+Sheet2!E$13 -> 19.098353 | BC9: =AE9-AVERAGE(AE$2:AE$31)+Sheet2!F$13 -> 24.123864 | BD9: =AF9-AVERAGE(AF$2:AF$31)+Sheet2!G$13 -> 21.517772 | BE9: =AG9-AVERAGE(AG$2:AG$31)+Sheet2!H$13 -> 33.007507 | BF9: =AH9-AVERAGE(AH$2:AH$31)+Sheet2!I$13 -> 12.773985 | BG9: =AI9-AVERAGE(AI$2:AI$31)+Sheet2!J$13 -> 19.462264 | ... BW9: =AY9-AVERAGE(AY$2:AY$31)+Sheet2!Z$13 -> 9.0962076 | BZ9: =BA9-AVERAGE(BA$2:BA$31)+Sheet2!AB$13 -> 0.041155394 | CA9: =BB9-AVERAGE(BB$2:BB$31)+Sheet2!AC$13 -> 0.47440316 | CB9: =BC9-AVERAGE(BC$2:BC$31)+Sheet2!AD$13 -> 3.0330029 | CC9: =BD9-AVERAGE(BD$2:BD$31)+Sheet2!AE$13 -> 2.3559892
B10: 9 | C10: 1 | D10: =RAND() -> 0.071819088 | E10: =RAND() -> 0.75437959 | F10: =RAND() -> 0.93512248 | G10: =RAND() -> 0.63646603 | H10: =RAND() -> 0.95263062 | I10: =RAND() -> 0.47403951 | J10: =RAND() -> 0.16622424 | K10: =RAND() -> 0.40224168 | ... AA10: =RAND() -> 0.32041536 | AB10: =D10*Sheet2!C$14/_xlfn.STDEV.S(D$2:D$31) -> 0.14411358 | AC10: =E10*Sheet2!D$14/_xlfn.STDEV.S(E$2:E$31) -> 5.5329072 | AD10: =F10*Sheet2!E$14/_xlfn.STDEV.S(F$2:F$31) -> 4.3659463 | AE10: =G10*Sheet2!F$14/_xlfn.STDEV.S(G$2:G$31) -> 5.1898436 | AF10: =H10*Sheet2!G$14/_xlfn.STDEV.S(H$2:H$31) -> 6.1178696 | AG10: =I10*Sheet2!H$14/_xlfn.STDEV.S(I$2:I$31) -> 5.1099467 | AH10: =J10*Sheet2!I$14/_xlfn.STDEV.S(J$2:J$31) -> 0.40516712 | AI10: =K10*Sheet2!J$14/_xlfn.STDEV.S(K$2:K$31) -> 1.1815774 | ... AY10: =AA10*Sheet2!Z$14/_xlfn.STDEV.S(AA$2:AA$31) -> 0.76858218 | AZ10: =AB10-AVERAGE(AB$2:AB$31)+Sheet2!C$13 -> 2.4023314 | BA10: =AC10-AVERAGE(AC$2:AC$31)+Sheet2!D$13 -> 8.5374417 | BB10: =AD10-AVERAGE(AD$2:AD$31)+Sheet2!E$13 -> 20.0403 | BC10: =AE10-AVERAGE(AE$2:AE$31)+Sheet2!F$13 -> 22.166059 | BD10: =AF10-AVERAGE(AF$2:AF$31)+Sheet2!G$13 -> 22.204752 | BE10: =AG10-AVERAGE(AG$2:AG$31)+Sheet2!H$13 -> 28.730762 | BF10: =AH10-AVERAGE(AH$2:AH$31)+Sheet2!I$13 -> 11.190353 | BG10: =AI10-AVERAGE(AI$2:AI$31)+Sheet2!J$13 -> 19.422946 | ... BW10: =AY10-AVERAGE(AY$2:AY$31)+Sheet2!Z$13 -> 7.6537719 | BZ10: =BA10-AVERAGE(BA$2:BA$31)+Sheet2!AB$13 -> 1.7732302 | CA10: =BB10-AVERAGE(BB$2:BB$31)+Sheet2!AC$13 -> 1.4163503 | CB10: =BC10-AVERAGE(BC$2:BC$31)+Sheet2!AD$13 -> 1.0751978 | CC10: =BD10-AVERAGE(BD$2:BD$31)+Sheet2!AE$13 -> 3.0429693
B11: 10 | C11: 1 | D11: =RAND() -> 0.50370934 | E11: =RAND() -> 0.50471334 | F11: =RAND() -> 0.040162938 | G11: =RAND() -> 0.5078076 | H11: =RAND() -> 0.24301974 | I11: =RAND() -> 0.64516124 | J11: =RAND() -> 0.35627477 | K11: =RAND() -> 0.80925587 | ... AA11: =RAND() -> 0.11815166 | AB11: =D11*Sheet2!C$14/_xlfn.STDEV.S(D$2:D$31) -> 1.0107529 | AC11: =E11*Sheet2!D$14/_xlfn.STDEV.S(E$2:E$31) -> 3.7017598 | AD11: =F11*Sheet2!E$14/_xlfn.STDEV.S(F$2:F$31) -> 0.18751472 | AE11: =G11*Sheet2!F$14/_xlfn.STDEV.S(G$2:G$31) -> 4.1407426 | AF11: =H11*Sheet2!G$14/_xlfn.STDEV.S(H$2:H$31) -> 1.5606921 | AG11: =I11*Sheet2!H$14/_xlfn.STDEV.S(I$2:I$31) -> 6.9545671 | AH11: =J11*Sheet2!I$14/_xlfn.STDEV.S(J$2:J$31) -> 0.86841022 | AI11: =K11*Sheet2!J$14/_xlfn.STDEV.S(K$2:K$31) -> 2.377174 | ... AY11: =AA11*Sheet2!Z$14/_xlfn.STDEV.S(AA$2:AA$31) -> 0.28341108 | AZ11: =AB11-AVERAGE(AB$2:AB$31)+Sheet2!C$13 -> 3.2689708 | BA11: =AC11-AVERAGE(AC$2:AC$31)+Sheet2!D$13 -> 6.7062943 | BB11: =AD11-AVERAGE(AD$2:AD$31)+Sheet2!E$13 -> 15.861868 | BC11: =AE11-AVERAGE(AE$2:AE$31)+Sheet2!F$13 -> 21.116958 | BD11: =AF11-AVERAGE(AF$2:AF$31)+Sheet2!G$13 -> 17.647575 | BE11: =AG11-AVERAGE(AG$2:AG$31)+Sheet2!H$13 -> 30.575382 | BF11: =AH11-AVERAGE(AH$2:AH$31)+Sheet2!I$13 -> 11.653596 | BG11: =AI11-AVERAGE(AI$2:AI$31)+Sheet2!J$13 -> 20.618543 | ... BW11: =AY11-AVERAGE(AY$2:AY$31)+Sheet2!Z$13 -> 7.1686008 | BZ11: =BA11-AVERAGE(BA$2:BA$31)+Sheet2!AB$13 -> -0.057917185 | CA11: =BB11-AVERAGE(BB$2:BB$31)+Sheet2!AC$13 -> -2.7620813 | CB11: =BC11-AVERAGE(BC$2:BC$31)+Sheet2!AD$13 -> 0.026096829 | CC11: =BD11-AVERAGE(BD$2:BD$31)+Sheet2!AE$13 -> -1.5142082
B12: 11 | C12: 1 | D12: =RAND() -> 0.0025052945 | E12: =RAND() -> 0.92897582 | F12: =RAND() -> 0.88222114 | G12: =RAND() -> 0.42710448 | H12: =RAND() -> 0.41958462 | I12: =RAND() -> 0.30690419 | J12: =RAND() -> 0.20963127 | K12: =RAND() -> 0.56910123 | ... AA12: =RAND() -> 0.54040616 | AB12: =D12*Sheet2!C$14/_xlfn.STDEV.S(D$2:D$31) -> 0.0050271725 | AC12: =E12*Sheet2!D$14/_xlfn.STDEV.S(E$2:E$31) -> 6.8134624 | AD12: =F12*Sheet2!E$14/_xlfn.STDEV.S(F$2:F$31) -> 4.1189579 | AE12: =G12*Sheet2!F$14/_xlfn.STDEV.S(G$2:G$31) -> 3.4826768 | AF12: =H12*Sheet2!G$14/_xlfn.STDEV.S(H$2:H$31) -> 2.6946058 | AG12: =I12*Sheet2!H$14/_xlfn.STDEV.S(I$2:I$31) -> 3.3082982 | AH12: =J12*Sheet2!I$14/_xlfn.STDEV.S(J$2:J$31) -> 0.51097059 | AI12: =K12*Sheet2!J$14/_xlfn.STDEV.S(K$2:K$31) -> 1.6717242 | ... AY12: =AA12*Sheet2!Z$14/_xlfn.STDEV.S(AA$2:AA$31) -> 1.2962754 | AZ12: =AB12-AVERAGE(AB$2:AB$31)+Sheet2!C$13 -> 2.263245 | BA12: =AC12-AVERAGE(AC$2:AC$31)+Sheet2!D$13 -> 9.8179969 | BB12: =AD12-AVERAGE(AD$2:AD$31)+Sheet2!E$13 -> 19.793311 | BC12: =AE12-AVERAGE(AE$2:AE$31)+Sheet2!F$13 -> 20.458892 | BD12: =AF12-AVERAGE(AF$2:AF$31)+Sheet2!G$13 -> 18.781488 | BE12: =AG12-AVERAGE(AG$2:AG$31)+Sheet2!H$13 -> 26.929113 | BF12: =AH12-AVERAGE(AH$2:AH$31)+Sheet2!I$13 -> 11.296156 | BG12: =AI12-AVERAGE(AI$2:AI$31)+Sheet2!J$13 -> 19.913093 | ... BW12: =AY12-AVERAGE(AY$2:AY$31)+Sheet2!Z$13 -> 8.1814651 | BZ12: =BA12-AVERAGE(BA$2:BA$31)+Sheet2!AB$13 -> 3.0537854 | CA12: =BB12-AVERAGE(BB$2:BB$31)+Sheet2!AC$13 -> 1.1693619 | CB12: =BC12-AVERAGE(BC$2:BC$31)+Sheet2!AD$13 -> -0.63196903 | CC12: =BD12-AVERAGE(BD$2:BD$31)+Sheet2!AE$13 -> -0.38029448
B13: 12 | C13: 1 | D13: =RAND() -> 0.061888698 | E13: =RAND() -> 0.82120652 | F13: =RAND() -> 0.98762838 | G13: =RAND() -> 0.093504435 | H13: =RAND() -> 0.84685598 | I13: =RAND() -> 0.53286097 | J13: =RAND() -> 0.78761751 | K13: =RAND() -> 0.8136357 | ... AA13: =RAND() -> 0.31480556 | AB13: =D13*Sheet2!C$14/_xlfn.STDEV.S(D$2:D$31) -> 0.12418706 | AC13: =E13*Sheet2!D$14/_xlfn.STDEV.S(E$2:E$31) -> 6.0230414 | AD13: =F13*Sheet2!E$14/_xlfn.STDEV.S(F$2:F$31) -> 4.6110885 | AE13: =G13*Sheet2!F$14/_xlfn.STDEV.S(G$2:G$31) -> 0.76244979 | AF13: =H13*Sheet2!G$14/_xlfn.STDEV.S(H$2:H$31) -> 5.4385765 | AG13: =I13*Sheet2!H$14/_xlfn.STDEV.S(I$2:I$31) -> 5.7440174 | AH13: =J13*Sheet2!I$14/_xlfn.STDEV.S(J$2:J$31) -> 1.9197966 | AI13: =K13*Sheet2!J$14/_xlfn.STDEV.S(K$2:K$31) -> 2.3900397 | ... AY13: =AA13*Sheet2!Z$14/_xlfn.STDEV.S(AA$2:AA$31) -> 0.75512594 | AZ13: =AB13-AVERAGE(AB$2:AB$31)+Sheet2!C$13 -> 2.3824049 | BA13: =AC13-AVERAGE(AC$2:AC$31)+Sheet2!D$13 -> 9.0275759 | BB13: =AD13-AVERAGE(AD$2:AD$31)+Sheet2!E$13 -> 20.285442 | BC13: =AE13-AVERAGE(AE$2:AE$31)+Sheet2!F$13 -> 17.738665 | BD13: =AF13-AVERAGE(AF$2:AF$31)+Sheet2!G$13 -> 21.525459 | BE13: =AG13-AVERAGE(AG$2:AG$31)+Sheet2!H$13 -> 29.364832 | BF13: =AH13-AVERAGE(AH$2:AH$31)+Sheet2!I$13 -> 12.704982 | BG13: =AI13-AVERAGE(AI$2:AI$31)+Sheet2!J$13 -> 20.631408 | ... BW13: =AY13-AVERAGE(AY$2:AY$31)+Sheet2!Z$13 -> 7.6403157 | BZ13: =BA13-AVERAGE(BA$2:BA$31)+Sheet2!AB$13 -> 2.2633644 | CA13: =BB13-AVERAGE(BB$2:BB$31)+Sheet2!AC$13 -> 1.6614924 | CB13: =BC13-AVERAGE(BC$2:BC$31)+Sheet2!AD$13 -> -3.352196 | CC13: =BD13-AVERAGE(BD$2:BD$31)+Sheet2!AE$13 -> 2.3636762
... B31: 30 | C31: 1 | D31: =RAND() -> 0.75924105 | E31: =RAND() -> 0.78551801 | F31: =RAND() -> 0.7141686 | G31: =RAND() -> 0.21376148 | H31: =RAND() -> 0.55092353 | I31: =RAND() -> 0.44560814 | J31: =RAND() -> 0.14284663 | K31: =RAND() -> 0.086259508 | ... AA31: =RAND() -> 0.12440671 | AB31: =D31*Sheet2!C$14/_xlfn.STDEV.S(D$2:D$31) -> 1.5235078 | AC31: =E31*Sheet2!D$14/_xlfn.STDEV.S(E$2:E$31) -> 5.7612882 | AD31: =F31*Sheet2!E$14/_xlfn.STDEV.S(F$2:F$31) -> 3.3343459 | AE31: =G31*Sheet2!F$14/_xlfn.STDEV.S(G$2:G$31) -> 1.7430445 | AF31: =H31*Sheet2!G$14/_xlfn.STDEV.S(H$2:H$31) -> 3.5380748 | AG31: =I31*Sheet2!H$14/_xlfn.STDEV.S(I$2:I$31) -> 4.8034685 | AH31: =J31*Sheet2!I$14/_xlfn.STDEV.S(J$2:J$31) -> 0.34818484 | AI31: =K31*Sheet2!J$14/_xlfn.STDEV.S(K$2:K$31) -> 0.2533857 | ... AY31: =AA31*Sheet2!Z$14/_xlfn.STDEV.S(AA$2:AA$31) -> 0.2984151 | AZ31: =AB31-AVERAGE(AB$2:AB$31)+Sheet2!C$13 -> 3.7817256 | BA31: =AC31-AVERAGE(AC$2:AC$31)+Sheet2!D$13 -> 8.7658227 | BB31: =AD31-AVERAGE(AD$2:AD$31)+Sheet2!E$13 -> 19.008699 | BC31: =AE31-AVERAGE(AE$2:AE$31)+Sheet2!F$13 -> 18.71926 | BD31: =AF31-AVERAGE(AF$2:AF$31)+Sheet2!G$13 -> 19.624957 | BE31: =AG31-AVERAGE(AG$2:AG$31)+Sheet2!H$13 -> 28.424283 | BF31: =AH31-AVERAGE(AH$2:AH$31)+Sheet2!I$13 -> 11.13337 | BG31: =AI31-AVERAGE(AI$2:AI$31)+Sheet2!J$13 -> 18.494754 | ... BW31: =AY31-AVERAGE(AY$2:AY$31)+Sheet2!Z$13 -> 7.1836048 | BZ31: =BA31-AVERAGE(BA$2:BA$31)+Sheet2!AB$13 -> 2.0016112 | CA31: =BB31-AVERAGE(BB$2:BB$31)+Sheet2!AC$13 -> 0.38474983 | CB31: =BC31-AVERAGE(BC$2:BC$31)+Sheet2!AD$13 -> -2.3716012 | CC31: =BD31-AVERAGE(BD$2:BD$31)+Sheet2!AE$13 -> 0.46317446
B32: 31 | C32: 2 | D32: =RAND() -> 0.52796672 | E32: =RAND() -> 0.39419202 | F32: =RAND() -> 0.46918804 | G32: =RAND() -> 0.54302718 | H32: =RAND() -> 0.25629617 | I32: =RAND() -> 0.40973256 | J32: =RAND() -> 0.52949943 | K32: =RAND() -> 0.60238322 | ... AA32: =RAND() -> 0.31770549 | AB32: =D32*Sheet2!C$16/_xlfn.STDEV.S(D$32:D$61) -> 2.5444117 | AC32: =E32*Sheet2!D$16/_xlfn.STDEV.S(E$32:E$61) -> 2.808757 | AD32: =F32*Sheet2!E$16/_xlfn.STDEV.S(F$32:F$61) -> 2.677144 | AE32: =G32*Sheet2!F$16/_xlfn.STDEV.S(G$32:G$61) -> 4.4497821 | AF32: =H32*Sheet2!G$16/_xlfn.STDEV.S(H$32:H$61) -> 3.929494 | AG32: =I32*Sheet2!H$16/_xlfn.STDEV.S(I$32:I$61) -> 4.3894219 | AH32: =J32*Sheet2!I$16/_xlfn.STDEV.S(J$32:J$61) -> 1.2849508 | AI32: =K32*Sheet2!J$16/_xlfn.STDEV.S(K$32:K$61) -> 2.0086439 | ... AY32: =AA32*Sheet2!Z$16/_xlfn.STDEV.S(AA$32:AA$61) -> 0.58526856 | AZ32: =AB32-AVERAGE(AB$32:AB$61)+Sheet2!C$15 -> 4.5510196 | BA32: =AC32-AVERAGE(AC$32:AC$61)+Sheet2!D$15 -> 8.1690721 | BB32: =AD32-AVERAGE(AD$32:AD$61)+Sheet2!E$15 -> 17.456491 | BC32: =AE32-AVERAGE(AE$32:AE$61)+Sheet2!F$15 -> 17.202541 | BD32: =AF32-AVERAGE(AF$32:AF$61)+Sheet2!G$15 -> 18.476442 | BE32: =AG32-AVERAGE(AG$32:AG$61)+Sheet2!H$15 -> 29.786297 | BF32: =AH32-AVERAGE(AH$32:AH$61)+Sheet2!I$15 -> 12.617198 | BG32: =AI32-AVERAGE(AI$32:AI$61)+Sheet2!J$15 -> 22.646957 | ... BW32: =AY32-AVERAGE(AY$32:AY$61)+Sheet2!Z$15 -> 7.629403 | BZ32: =BA32-AVERAGE(AH$32:AH$61)+Sheet2!AB$15 -> 6.8525245 | CA32: =BB32-AVERAGE(AI$32:AI$61)+Sheet2!AC$15 -> 15.996102 | CB32: =BC32-AVERAGE(AJ$32:AJ$61)+Sheet2!AD$15 -> 14.174693 | CC32: =BD32-AVERAGE(AK$32:AK$61)+Sheet2!AE$15 -> 15.814486
B33: 32 | C33: 2 | D33: =RAND() -> 0.55278508 | E33: =RAND() -> 0.85327497 | F33: =RAND() -> 0.15994417 | G33: =RAND() -> 0.115942 | H33: =RAND() -> 0.33744418 | I33: =RAND() -> 0.74583347 | J33: =RAND() -> 0.56611461 | K33: =RAND() -> 0.73117332 | ... AA33: =RAND() -> 0.026672072 | AB33: =D33*Sheet2!C$16/_xlfn.STDEV.S(D$32:D$61) -> 2.664018 | AC33: =E33*Sheet2!D$16/_xlfn.STDEV.S(E$32:E$61) -> 6.0798848 | AD33: =F33*Sheet2!E$16/_xlfn.STDEV.S(F$32:F$61) -> 0.91262679 | AE33: =G33*Sheet2!F$16/_xlfn.STDEV.S(G$32:G$61) -> 0.95007517 | AF33: =H33*Sheet2!G$16/_xlfn.STDEV.S(H$32:H$61) -> 5.173643 | AG33: =I33*Sheet2!H$16/_xlfn.STDEV.S(I$32:I$61) -> 7.9900357 | AH33: =J33*Sheet2!I$16/_xlfn.STDEV.S(J$32:J$61) -> 1.3738058 | AI33: =K33*Sheet2!J$16/_xlfn.STDEV.S(K$32:K$61) -> 2.4380939 | ... AY33: =AA33*Sheet2!Z$16/_xlfn.STDEV.S(AA$32:AA$61) -> 0.049134579 | AZ33: =AB33-AVERAGE(AB$32:AB$61)+Sheet2!C$15 -> 4.6706258 | BA33: =AC33-AVERAGE(AC$32:AC$61)+Sheet2!D$15 -> 11.4402 | BB33: =AD33-AVERAGE(AD$32:AD$61)+Sheet2!E$15 -> 15.691974 | BC33: =AE33-AVERAGE(AE$32:AE$61)+Sheet2!F$15 -> 13.702834 | BD33: =AF33-AVERAGE(AF$32:AF$61)+Sheet2!G$15 -> 19.720591 | BE33: =AG33-AVERAGE(AG$32:AG$61)+Sheet2!H$15 -> 33.386911 | BF33: =AH33-AVERAGE(AH$32:AH$61)+Sheet2!I$15 -> 12.706053 | BG33: =AI33-AVERAGE(AI$32:AI$61)+Sheet2!J$15 -> 23.076407 | ... BW33: =AY33-AVERAGE(AY$32:AY$61)+Sheet2!Z$15 -> 7.093269 | BZ33: =BA33-AVERAGE(AH$32:AH$61)+Sheet2!AB$15 -> 10.123652 | CA33: =BB33-AVERAGE(AI$32:AI$61)+Sheet2!AC$15 -> 14.231584 | CB33: =BC33-AVERAGE(AJ$32:AJ$61)+Sheet2!AD$15 -> 10.674986 | CC33: =BD33-AVERAGE(AK$32:AK$61)+Sheet2!AE$15 -> 17.058635
B34: 33 | C34: 2 | D34: =RAND() -> 0.37132146 | E34: =RAND() -> 0.68430779 | F34: =RAND() -> 0.16875106 | G34: =RAND() -> 0.48850398 | H34: =RAND() -> 0.64818737 | I34: =RAND() -> 0.44641264 | J34: =RAND() -> 0.015721293 | K34: =RAND() -> 0.13145668 | ... AA34: =RAND() -> 0.29760837 | AB34: =D34*Sheet2!C$16/_xlfn.STDEV.S(D$32:D$61) -> 1.7894966 | AC34: =E34*Sheet2!D$16/_xlfn.STDEV.S(E$32:E$61) -> 4.8759341 | AD34: =F34*Sheet2!E$16/_xlfn.STDEV.S(F$32:F$61) -> 0.96287809 | AE34: =G34*Sheet2!F$16/_xlfn.STDEV.S(G$32:G$61) -> 4.0029972 | AF34: =H34*Sheet2!G$16/_xlfn.STDEV.S(H$32:H$61) -> 9.9379105 | AG34: =I34*Sheet2!H$16/_xlfn.STDEV.S(I$32:I$61) -> 4.7823718 | AH34: =J34*Sheet2!I$16/_xlfn.STDEV.S(J$32:J$61) -> 0.038151293 | AI34: =K34*Sheet2!J$16/_xlfn.STDEV.S(K$32:K$61) -> 0.43834165 | ... AY34: =AA34*Sheet2!Z$16/_xlfn.STDEV.S(AA$32:AA$61) -> 0.54824619 | AZ34: =AB34-AVERAGE(AB$32:AB$61)+Sheet2!C$15 -> 3.7961045 | BA34: =AC34-AVERAGE(AC$32:AC$61)+Sheet2!D$15 -> 10.236249 | BB34: =AD34-AVERAGE(AD$32:AD$61)+Sheet2!E$15 -> 15.742225 | BC34: =AE34-AVERAGE(AE$32:AE$61)+Sheet2!F$15 -> 16.755756 | BD34: =AF34-AVERAGE(AF$32:AF$61)+Sheet2!G$15 -> 24.484859 | BE34: =AG34-AVERAGE(AG$32:AG$61)+Sheet2!H$15 -> 30.179247 | BF34: =AH34-AVERAGE(AH$32:AH$61)+Sheet2!I$15 -> 11.370398 | BG34: =AI34-AVERAGE(AI$32:AI$61)+Sheet2!J$15 -> 21.076655 | ... BW34: =AY34-AVERAGE(AY$32:AY$61)+Sheet2!Z$15 -> 7.5923807 | BZ34: =BA34-AVERAGE(AH$32:AH$61)+Sheet2!AB$15 -> 8.9197016 | CA34: =BB34-AVERAGE(AI$32:AI$61)+Sheet2!AC$15 -> 14.281836 | CB34: =BC34-AVERAGE(AJ$32:AJ$61)+Sheet2!AD$15 -> 13.727909 | CC34: =BD34-AVERAGE(AK$32:AK$61)+Sheet2!AE$15 -> 21.822903
B35: 34 | C35: 2 | D35: =RAND() -> 0.28628894 | E35: =RAND() -> 0.91070927 | F35: =RAND() -> 0.0646576 | G35: =RAND() -> 0.75294989 | H35: =RAND() -> 0.51722253 | I35: =RAND() -> 0.7986075 | J35: =RAND() -> 0.88546907 | K35: =RAND() -> 0.41906254 | ... AA35: =RAND() -> 0.5649572 | AB35: =D35*Sheet2!C$16/_xlfn.STDEV.S(D$32:D$61) -> 1.3797024 | AC35: =E35*Sheet2!D$16/_xlfn.STDEV.S(E$32:E$61) -> 6.4891244 | AD35: =F35*Sheet2!E$16/_xlfn.STDEV.S(F$32:F$61) -> 0.36893035 | AE35: =G35*Sheet2!F$16/_xlfn.STDEV.S(G$32:G$61) -> 6.1699729 | AF35: =H35*Sheet2!G$16/_xlfn.STDEV.S(H$32:H$61) -> 7.9299774 | AG35: =I35*Sheet2!H$16/_xlfn.STDEV.S(I$32:I$61) -> 8.5553983 | AH35: =J35*Sheet2!I$16/_xlfn.STDEV.S(J$32:J$61) -> 2.148792 | AI35: =K35*Sheet2!J$16/_xlfn.STDEV.S(K$32:K$61) -> 1.397362 | ... AY35: =AA35*Sheet2!Z$16/_xlfn.STDEV.S(AA$32:AA$61) -> 1.0407491 | AZ35: =AB35-AVERAGE(AB$32:AB$61)+Sheet2!C$15 -> 3.3863102 | BA35: =AC35-AVERAGE(AC$32:AC$61)+Sheet2!D$15 -> 11.84944 | BB35: =AD35-AVERAGE(AD$32:AD$61)+Sheet2!E$15 -> 15.148277 | BC35: =AE35-AVERAGE(AE$32:AE$61)+Sheet2!F$15 -> 18.922731 | BD35: =AF35-AVERAGE(AF$32:AF$61)+Sheet2!G$15 -> 22.476925 | BE35: =AG35-AVERAGE(AG$32:AG$61)+Sheet2!H$15 -> 33.952273 | BF35: =AH35-AVERAGE(AH$32:AH$61)+Sheet2!I$15 -> 13.481039 | BG35: =AI35-AVERAGE(AI$32:AI$61)+Sheet2!J$15 -> 22.035675 | ... BW35: =AY35-AVERAGE(AY$32:AY$61)+Sheet2!Z$15 -> 8.0848835 | BZ35: =BA35-AVERAGE(AH$32:AH$61)+Sheet2!AB$15 -> 10.532892 | CA35: =BB35-AVERAGE(AI$32:AI$61)+Sheet2!AC$15 -> 13.687888 | CB35: =BC35-AVERAGE(AJ$32:AJ$61)+Sheet2!AD$15 -> 15.894884 | CC35: =BD35-AVERAGE(AK$32:AK$61)+Sheet2!AE$15 -> 19.81497
B36: 35 | C36: 2 | D36: =RAND() -> 0.58919617 | E36: =RAND() -> 0.70371008 | F36: =RAND() -> 0.56732755 | G36: =RAND() -> 0.48824121 | H36: =RAND() -> 0.17044273 | I36: =RAND() -> 0.14372716 | J36: =RAND() -> 0.76551251 | K36: =RAND() -> 0.17241372 | ... AA36: =RAND() -> 0.025614914 | AB36: =D36*Sheet2!C$16/_xlfn.STDEV.S(D$32:D$61) -> 2.8394926 | AC36: =E36*Sheet2!D$16/_xlfn.STDEV.S(E$32:E$61) -> 5.0141822 | AD36: =F36*Sheet2!E$16/_xlfn.STDEV.S(F$32:F$61) -> 3.2371191 | AE36: =G36*Sheet2!F$16/_xlfn.STDEV.S(G$32:G$61) -> 4.000844 | AF36: =H36*Sheet2!G$16/_xlfn.STDEV.S(H$32:H$61) -> 2.613202 | AG36: =I36*Sheet2!H$16/_xlfn.STDEV.S(I$32:I$61) -> 1.5397339 | AH36: =J36*Sheet2!I$16/_xlfn.STDEV.S(J$32:J$61) -> 1.8576902 | AI36: =K36*Sheet2!J$16/_xlfn.STDEV.S(K$32:K$61) -> 0.57491269 | ... AY36: =AA36*Sheet2!Z$16/_xlfn.STDEV.S(AA$32:AA$61) -> 0.04718711 | AZ36: =AB36-AVERAGE(AB$32:AB$61)+Sheet2!C$15 -> 4.8461005 | BA36: =AC36-AVERAGE(AC$32:AC$61)+Sheet2!D$15 -> 10.374497 | BB36: =AD36-AVERAGE(AD$32:AD$61)+Sheet2!E$15 -> 18.016466 | BC36: =AE36-AVERAGE(AE$32:AE$61)+Sheet2!F$15 -> 16.753603 | BD36: =AF36-AVERAGE(AF$32:AF$61)+Sheet2!G$15 -> 17.16015 | BE36: =AG36-AVERAGE(AG$32:AG$61)+Sheet2!H$15 -> 26.936609 | BF36: =AH36-AVERAGE(AH$32:AH$61)+Sheet2!I$15 -> 13.189937 | BG36: =AI36-AVERAGE(AI$32:AI$61)+Sheet2!J$15 -> 21.213226 | ... BW36: =AY36-AVERAGE(AY$32:AY$61)+Sheet2!Z$15 -> 7.0913216 | BZ36: =BA36-AVERAGE(AH$32:AH$61)+Sheet2!AB$15 -> 9.0579497 | CA36: =BB36-AVERAGE(AI$32:AI$61)+Sheet2!AC$15 -> 16.556077 | CB36: =BC36-AVERAGE(AJ$32:AJ$61)+Sheet2!AD$15 -> 13.725755 | CC36: =BD36-AVERAGE(AK$32:AK$61)+Sheet2!AE$15 -> 14.498194
B37: 36 | C37: 2 | D37: =RAND() -> 0.67174398 | E37: =RAND() -> 0.40702872 | F37: =RAND() -> 0.39428849 | G37: =RAND() -> 0.20479352 | H37: =RAND() -> 0.12382422 | I37: =RAND() -> 0.35771466 | J37: =RAND() -> 0.48208409 | K37: =RAND() -> 0.22855008 | ... AA37: =RAND() -> 0.95394171 | AB37: =D37*Sheet2!C$16/_xlfn.STDEV.S(D$32:D$61) -> 3.2373125 | AC37: =E37*Sheet2!D$16/_xlfn.STDEV.S(E$32:E$61) -> 2.900223 | AD37: =F37*Sheet2!E$16/_xlfn.STDEV.S(F$32:F$61) -> 2.2497741 | AE37: =G37*Sheet2!F$16/_xlfn.STDEV.S(G$32:G$61) -> 1.6781601 | AF37: =H37*Sheet2!G$16/_xlfn.STDEV.S(H$32:H$61) -> 1.8984541 | AG37: =I37*Sheet2!H$16/_xlfn.STDEV.S(I$32:I$61) -> 3.8321597 | AH37: =J37*Sheet2!I$16/_xlfn.STDEV.S(J$32:J$61) -> 1.1698867 | AI37: =K37*Sheet2!J$16/_xlfn.STDEV.S(K$32:K$61) -> 0.76209912 | ... AY37: =AA37*Sheet2!Z$16/_xlfn.STDEV.S(AA$32:AA$61) -> 1.7573259 | AZ37: =AB37-AVERAGE(AB$32:AB$61)+Sheet2!C$15 -> 5.2439203 | BA37: =AC37-AVERAGE(AC$32:AC$61)+Sheet2!D$15 -> 8.2605381 | BB37: =AD37-AVERAGE(AD$32:AD$61)+Sheet2!E$15 -> 17.029121 | BC37: =AE37-AVERAGE(AE$32:AE$61)+Sheet2!F$15 -> 14.430919 | BD37: =AF37-AVERAGE(AF$32:AF$61)+Sheet2!G$15 -> 16.445402 | BE37: =AG37-AVERAGE(AG$32:AG$61)+Sheet2!H$15 -> 29.229034 | BF37: =AH37-AVERAGE(AH$32:AH$61)+Sheet2!I$15 -> 12.502134 | BG37: =AI37-AVERAGE(AI$32:AI$61)+Sheet2!J$15 -> 21.400413 | ... BW37: =AY37-AVERAGE(AY$32:AY$61)+Sheet2!Z$15 -> 8.8014604 | BZ37: =BA37-AVERAGE(AH$32:AH$61)+Sheet2!AB$15 -> 6.9439905 | CA37: =BB37-AVERAGE(AI$32:AI$61)+Sheet2!AC$15 -> 15.568732 | CB37: =BC37-AVERAGE(AJ$32:AJ$61)+Sheet2!AD$15 -> 11.403071 | CC37: =BD37-AVERAGE(AK$32:AK$61)+Sheet2!AE$15 -> 13.783446
B38: 37 | C38: 2 | D38: =RAND() -> 0.95995084 | E38: =RAND() -> 0.74972197 | F38: =RAND() -> 0.74824523 | G38: =RAND() -> 0.3963808 | H38: =RAND() -> 0.31735137 | I38: =RAND() -> 0.45650429 | J38: =RAND() -> 0.85416777 | K38: =RAND() -> 0.22273922 | ... AA38: =RAND() -> 0.46238712 | AB38: =D38*Sheet2!C$16/_xlfn.STDEV.S(D$32:D$61) -> 4.6262578 | AC38: =E38*Sheet2!D$16/_xlfn.STDEV.S(E$32:E$61) -> 5.3420332 | AD38: =F38*Sheet2!E$16/_xlfn.STDEV.S(F$32:F$61) -> 4.2694189 | AE38: =G38*Sheet2!F$16/_xlfn.STDEV.S(G$32:G$61) -> 3.248103 | AF38: =H38*Sheet2!G$16/_xlfn.STDEV.S(H$32:H$61) -> 4.8655831 | AG38: =I38*Sheet2!H$16/_xlfn.STDEV.S(I$32:I$61) -> 4.8904825 | AH38: =J38*Sheet2!I$16/_xlfn.STDEV.S(J$32:J$61) -> 2.0728323 | AI38: =K38*Sheet2!J$16/_xlfn.STDEV.S(K$32:K$61) -> 0.74272284 | ... AY38: =AA38*Sheet2!Z$16/_xlfn.STDEV.S(AA$32:AA$61) -> 0.85179721 | AZ38: =AB38-AVERAGE(AB$32:AB$61)+Sheet2!C$15 -> 6.6328656 | BA38: =AC38-AVERAGE(AC$32:AC$61)+Sheet2!D$15 -> 10.702348 | BB38: =AD38-AVERAGE(AD$32:AD$61)+Sheet2!E$15 -> 19.048766 | BC38: =AE38-AVERAGE(AE$32:AE$61)+Sheet2!F$15 -> 16.000862 | BD38: =AF38-AVERAGE(AF$32:AF$61)+Sheet2!G$15 -> 19.412531 | BE38: =AG38-AVERAGE(AG$32:AG$61)+Sheet2!H$15 -> 30.287357 | BF38: =AH38-AVERAGE(AH$32:AH$61)+Sheet2!I$15 -> 13.405079 | BG38: =AI38-AVERAGE(AI$32:AI$61)+Sheet2!J$15 -> 21.381036 | ... BW38: =AY38-AVERAGE(AY$32:AY$61)+Sheet2!Z$15 -> 7.8959317 | BZ38: =BA38-AVERAGE(AH$32:AH$61)+Sheet2!AB$15 -> 9.3858006 | CA38: =BB38-AVERAGE(AI$32:AI$61)+Sheet2!AC$15 -> 17.588376 | CB38: =BC38-AVERAGE(AJ$32:AJ$61)+Sheet2!AD$15 -> 12.973014 | CC38: =BD38-AVERAGE(AK$32:AK$61)+Sheet2!AE$15 -> 16.750575
B39: 38 | C39: 2 | D39: =RAND() -> 0.75575088 | E39: =RAND() -> 0.72303572 | F39: =RAND() -> 0.14378145 | G39: =RAND() -> 0.75199496 | H39: =RAND() -> 0.68852805 | I39: =RAND() -> 0.70637007 | J39: =RAND() -> 0.36044384 | K39: =RAND() -> 0.45444037 | ... AA39: =RAND() -> 0.89972436 | AB39: =D39*Sheet2!C$16/_xlfn.STDEV.S(D$32:D$61) -> 3.642164 | AC39: =E39*Sheet2!D$16/_xlfn.STDEV.S(E$32:E$61) -> 5.1518842 | AD39: =F39*Sheet2!E$16/_xlfn.STDEV.S(F$32:F$61) -> 0.82040381 | AE39: =G39*Sheet2!F$16/_xlfn.STDEV.S(G$32:G$61) -> 6.1621478 | AF39: =H39*Sheet2!G$16/_xlfn.STDEV.S(H$32:H$61) -> 10.556408 | AG39: =I39*Sheet2!H$16/_xlfn.STDEV.S(I$32:I$61) -> 7.5672684 | AH39: =J39*Sheet2!I$16/_xlfn.STDEV.S(J$32:J$61) -> 0.87469894 | AI39: =K39*Sheet2!J$16/_xlfn.STDEV.S(K$32:K$61) -> 1.5153292 | ... AY39: =AA39*Sheet2!Z$16/_xlfn.STDEV.S(AA$32:AA$61) -> 1.6574482 | AZ39: =AB39-AVERAGE(AB$32:AB$61)+Sheet2!C$15 -> 5.6487719 | BA39: =AC39-AVERAGE(AC$32:AC$61)+Sheet2!D$15 -> 10.512199 | BB39: =AD39-AVERAGE(AD$32:AD$61)+Sheet2!E$15 -> 15.599751 | BC39: =AE39-AVERAGE(AE$32:AE$61)+Sheet2!F$15 -> 18.914906 | BD39: =AF39-AVERAGE(AF$32:AF$61)+Sheet2!G$15 -> 25.103356 | BE39: =AG39-AVERAGE(AG$32:AG$61)+Sheet2!H$15 -> 32.964143 | BF39: =AH39-AVERAGE(AH$32:AH$61)+Sheet2!I$15 -> 12.206946 | BG39: =AI39-AVERAGE(AI$32:AI$61)+Sheet2!J$15 -> 22.153643 | ... BW39: =AY39-AVERAGE(AY$32:AY$61)+Sheet2!Z$15 -> 8.7015827 | BZ39: =BA39-AVERAGE(AH$32:AH$61)+Sheet2!AB$15 -> 9.1956517 | CA39: =BB39-AVERAGE(AI$32:AI$61)+Sheet2!AC$15 -> 14.139361 | CB39: =BC39-AVERAGE(AJ$32:AJ$61)+Sheet2!AD$15 -> 15.887059 | CC39: =BD39-AVERAGE(AK$32:AK$61)+Sheet2!AE$15 -> 22.4414
B40: 39 | C40: 2 | D40: =RAND() -> 0.53067768 | E40: =RAND() -> 0.49451341 | F40: =RAND() -> 0.69096219 | G40: =RAND() -> 0.81978792 | H40: =RAND() -> 0.77298393 | I40: =RAND() -> 0.019748704 | J40: =RAND() -> 0.89487328 | K40: =RAND() -> 0.16756757 | ... AA40: =RAND() -> 0.58144476 | AB40: =D40*Sheet2!C$16/_xlfn.STDEV.S(D$32:D$61) -> 2.5574765 | AC40: =E40*Sheet2!D$16/_xlfn.STDEV.S(E$32:E$61) -> 3.5235823 | AD40: =F40*Sheet2!E$16/_xlfn.STDEV.S(F$32:F$61) -> 3.9425671 | AE40: =G40*Sheet2!F$16/_xlfn.STDEV.S(G$32:G$61) -> 6.7176705 | AF40: =H40*Sheet2!G$16/_xlfn.STDEV.S(H$32:H$61) -> 11.851273 | AG40: =I40*Sheet2!H$16/_xlfn.STDEV.S(I$32:I$61) -> 0.2115658 | AH40: =J40*Sheet2!I$16/_xlfn.STDEV.S(J$32:J$61) -> 2.1716135 | AI40: =K40*Sheet2!J$16/_xlfn.STDEV.S(K$32:K$61) -> 0.55875322 | ... AY40: =AA40*Sheet2!Z$16/_xlfn.STDEV.S(AA$32:AA$61) -> 1.071122 | AZ40: =AB40-AVERAGE(AB$32:AB$61)+Sheet2!C$15 -> 4.5640843 | BA40: =AC40-AVERAGE(AC$32:AC$61)+Sheet2!D$15 -> 8.8838974 | BB40: =AD40-AVERAGE(AD$32:AD$61)+Sheet2!E$15 -> 18.721914 | BC40: =AE40-AVERAGE(AE$32:AE$61)+Sheet2!F$15 -> 19.470429 | BD40: =AF40-AVERAGE(AF$32:AF$61)+Sheet2!G$15 -> 26.398221 | BE40: =AG40-AVERAGE(AG$32:AG$61)+Sheet2!H$15 -> 25.608441 | BF40: =AH40-AVERAGE(AH$32:AH$61)+Sheet2!I$15 -> 13.503861 | BG40: =AI40-AVERAGE(AI$32:AI$61)+Sheet2!J$15 -> 21.197067 | ... BW40: =AY40-AVERAGE(AY$32:AY$61)+Sheet2!Z$15 -> 8.1152565 | BZ40: =BA40-AVERAGE(AH$32:AH$61)+Sheet2!AB$15 -> 7.5673498 | CA40: =BB40-AVERAGE(AI$32:AI$61)+Sheet2!AC$15 -> 17.261525 | CB40: =BC40-AVERAGE(AJ$32:AJ$61)+Sheet2!AD$15 -> 16.442582 | CC40: =BD40-AVERAGE(AK$32:AK$61)+Sheet2!AE$15 -> 23.736265
B41: 40 | C41: 2 | D41: =RAND() -> 0.39340502 | E41: =RAND() -> 0.55708185 | F41: =RAND() -> 0.53390768 | G41: =RAND() -> 0.16543477 | H41: =RAND() -> 0.33345309 | I41: =RAND() -> 0.0039140955 | J41: =RAND() -> 0.54573341 | K41: =RAND() -> 0.30630547 | ... AA41: =RAND() -> 0.99226581 | AB41: =D41*Sheet2!C$16/_xlfn.STDEV.S(D$32:D$61) -> 1.8959232 | AC41: =E41*Sheet2!D$16/_xlfn.STDEV.S(E$32:E$61) -> 3.9694045 | AD41: =F41*Sheet2!E$16/_xlfn.STDEV.S(F$32:F$61) -> 3.0464284 | AE41: =G41*Sheet2!F$16/_xlfn.STDEV.S(G$32:G$61) -> 1.3556388 | AF41: =H41*Sheet2!G$16/_xlfn.STDEV.S(H$32:H$61) -> 5.1124522 | AG41: =I41*Sheet2!H$16/_xlfn.STDEV.S(I$32:I$61) -> 0.041931295 | AH41: =J41*Sheet2!I$16/_xlfn.STDEV.S(J$32:J$61) -> 1.3243462 | AI41: =K41*Sheet2!J$16/_xlfn.STDEV.S(K$32:K$61) -> 1.0213741 | ... AY41: =AA41*Sheet2!Z$16/_xlfn.STDEV.S(AA$32:AA$61) -> 1.8279256 | AZ41: =AB41-AVERAGE(AB$32:AB$61)+Sheet2!C$15 -> 3.902531 | BA41: =AC41-AVERAGE(AC$32:AC$61)+Sheet2!D$15 -> 9.3297195 | BB41: =AD41-AVERAGE(AD$32:AD$61)+Sheet2!E$15 -> 17.825775 | BC41: =AE41-AVERAGE(AE$32:AE$61)+Sheet2!F$15 -> 14.108397 | BD41: =AF41-AVERAGE(AF$32:AF$61)+Sheet2!G$15 -> 19.6594 | BE41: =AG41-AVERAGE(AG$32:AG$61)+Sheet2!H$15 -> 25.438806 | BF41: =AH41-AVERAGE(AH$32:AH$61)+Sheet2!I$15 -> 12.656593 | BG41: =AI41-AVERAGE(AI$32:AI$61)+Sheet2!J$15 -> 21.659688 | ... BW41: =AY41-AVERAGE(AY$32:AY$61)+Sheet2!Z$15 -> 8.87206 | BZ41: =BA41-AVERAGE(AH$32:AH$61)+Sheet2!AB$15 -> 8.0131719 | CA41: =BB41-AVERAGE(AI$32:AI$61)+Sheet2!AC$15 -> 16.365386 | CB41: =BC41-AVERAGE(AJ$32:AJ$61)+Sheet2!AD$15 -> 11.08055 | CC41: =BD41-AVERAGE(AK$32:AK$61)+Sheet2!AE$15 -> 16.997444
B42: 41 | C42: 2 | D42: =RAND() -> 0.80814186 | E42: =RAND() -> 0.28417183 | F42: =RAND() -> 0.95078409 | G42: =RAND() -> 0.40163412 | H42: =RAND() -> 0.95040661 | I42: =RAND() -> 0.8861112 | J42: =RAND() -> 0.23764208 | K42: =RAND() -> 0.26741129 | ... AA42: =RAND() -> 0.85933777 | AB42: =D42*Sheet2!C$16/_xlfn.STDEV.S(D$32:D$61) -> 3.89465 | AC42: =E42*Sheet2!D$16/_xlfn.STDEV.S(E$32:E$61) -> 2.0248244 | AD42: =F42*Sheet2!E$16/_xlfn.STDEV.S(F$32:F$61) -> 5.425087 | AE42: =G42*Sheet2!F$16/_xlfn.STDEV.S(G$32:G$61) -> 3.2911508 | AF42: =H42*Sheet2!G$16/_xlfn.STDEV.S(H$32:H$61) -> 14.57149 | AG42: =I42*Sheet2!H$16/_xlfn.STDEV.S(I$32:I$61) -> 9.4928163 | AH42: =J42*Sheet2!I$16/_xlfn.STDEV.S(J$32:J$61) -> 0.57669253 | AI42: =K42*Sheet2!J$16/_xlfn.STDEV.S(K$32:K$61) -> 0.89168164 | ... AY42: =AA42*Sheet2!Z$16/_xlfn.STDEV.S(AA$32:AA$61) -> 1.5830491 | AZ42: =AB42-AVERAGE(AB$32:AB$61)+Sheet2!C$15 -> 5.9012579 | BA42: =AC42-AVERAGE(AC$32:AC$61)+Sheet2!D$15 -> 7.3851395 | BB42: =AD42-AVERAGE(AD$32:AD$61)+Sheet2!E$15 -> 20.204434 | BC42: =AE42-AVERAGE(AE$32:AE$61)+Sheet2!F$15 -> 16.043909 | BD42: =AF42-AVERAGE(AF$32:AF$61)+Sheet2!G$15 -> 29.118438 | BE42: =AG42-AVERAGE(AG$32:AG$61)+Sheet2!H$15 -> 34.889691 | BF42: =AH42-AVERAGE(AH$32:AH$61)+Sheet2!I$15 -> 11.90894 | BG42: =AI42-AVERAGE(AI$32:AI$61)+Sheet2!J$15 -> 21.529995 | ... BW42: =AY42-AVERAGE(AY$32:AY$61)+Sheet2!Z$15 -> 8.6271835 | BZ42: =BA42-AVERAGE(AH$32:AH$61)+Sheet2!AB$15 -> 6.0685919 | CA42: =BB42-AVERAGE(AI$32:AI$61)+Sheet2!AC$15 -> 18.744045 | CB42: =BC42-AVERAGE(AJ$32:AJ$61)+Sheet2!AD$15 -> 13.016062 | CC42: =BD42-AVERAGE(AK$32:AK$61)+Sheet2!AE$15 -> 26.456482
B43: 42 | C43: 2 | D43: =RAND() -> 0.55467472 | E43: =RAND() -> 0.41631438 | F43: =RAND() -> 0.016940477 | G43: =RAND() -> 0.23103017 | H43: =RAND() -> 0.55391551 | I43: =RAND() -> 0.2707178 | J43: =RAND() -> 0.85336376 | K43: =RAND() -> 0.57058719 | ... AA43: =RAND() -> 0.57405991 | AB43: =D43*Sheet2!C$16/_xlfn.STDEV.S(D$32:D$61) -> 2.6731246 | AC43: =E43*Sheet2!D$16/_xlfn.STDEV.S(E$32:E$61) -> 2.9663866 | AD43: =F43*Sheet2!E$16/_xlfn.STDEV.S(F$32:F$61) -> 0.096660815 | AE43: =G43*Sheet2!F$16/_xlfn.STDEV.S(G$32:G$61) -> 1.8931537 | AF43: =H43*Sheet2!G$16/_xlfn.STDEV.S(H$32:H$61) -> 8.4925487 | AG43: =I43*Sheet2!H$16/_xlfn.STDEV.S(I$32:I$61) -> 2.9001714 | AH43: =J43*Sheet2!I$16/_xlfn.STDEV.S(J$32:J$61) -> 2.0708812 | AI43: =K43*Sheet2!J$16/_xlfn.STDEV.S(K$32:K$61) -> 1.9026202 | ... AY43: =AA43*Sheet2!Z$16/_xlfn.STDEV.S(AA$32:AA$61) -> 1.0575178 | AZ43: =AB43-AVERAGE(AB$32:AB$61)+Sheet2!C$15 -> 4.6797325 | BA43: =AC43-AVERAGE(AC$32:AC$61)+Sheet2!D$15 -> 8.3267017 | BB43: =AD43-AVERAGE(AD$32:AD$61)+Sheet2!E$15 -> 14.876008 | BC43: =AE43-AVERAGE(AE$32:AE$61)+Sheet2!F$15 -> 14.645912 | BD43: =AF43-AVERAGE(AF$32:AF$61)+Sheet2!G$15 -> 23.039497 | BE43: =AG43-AVERAGE(AG$32:AG$61)+Sheet2!H$15 -> 28.297046 | BF43: =AH43-AVERAGE(AH$32:AH$61)+Sheet2!I$15 -> 13.403128 | BG43: =AI43-AVERAGE(AI$32:AI$61)+Sheet2!J$15 -> 22.540934 | ... BW43: =AY43-AVERAGE(AY$32:AY$61)+Sheet2!Z$15 -> 8.1016523 | BZ43: =BA43-AVERAGE(AH$32:AH$61)+Sheet2!AB$15 -> 7.0101541 | CA43: =BB43-AVERAGE(AI$32:AI$61)+Sheet2!AC$15 -> 13.415618 | CB43: =BC43-AVERAGE(AJ$32:AJ$61)+Sheet2!AD$15 -> 11.618065 | CC43: =BD43-AVERAGE(AK$32:AK$61)+Sheet2!AE$15 -> 20.377541
... B61: 60 | C61: 2 | D61: =RAND() -> 0.36322389 | E61: =RAND() -> 0.24311253 | F61: =RAND() -> 0.66808611 | G61: =RAND() -> 0.77831772 | H61: =RAND() -> 0.51498503 | I61: =RAND() -> 0.46672643 | J61: =RAND() -> 0.82213758 | K61: =RAND() -> 0.22633752 | ... AA61: =RAND() -> 0.90964548 | AB61: =D61*Sheet2!C$16/_xlfn.STDEV.S(D$32:D$61) -> 1.7504723 | AC61: =E61*Sheet2!D$16/_xlfn.STDEV.S(E$32:E$61) -> 1.7322624 | AD61: =F61*Sheet2!E$16/_xlfn.STDEV.S(F$32:F$61) -> 3.8120382 | AE61: =G61*Sheet2!F$16/_xlfn.STDEV.S(G$32:G$61) -> 6.3778471 | AF61: =H61*Sheet2!G$16/_xlfn.STDEV.S(H$32:H$61) -> 7.8956724 | AG61: =I61*Sheet2!H$16/_xlfn.STDEV.S(I$32:I$61) -> 4.9999913 | AH61: =J61*Sheet2!I$16/_xlfn.STDEV.S(J$32:J$61) -> 1.9951038 | AI61: =K61*Sheet2!J$16/_xlfn.STDEV.S(K$32:K$61) -> 0.75472133 | ... AY61: =AA61*Sheet2!Z$16/_xlfn.STDEV.S(AA$32:AA$61) -> 1.6757246 | AZ61: =AB61-AVERAGE(AB$32:AB$61)+Sheet2!C$15 -> 3.7570801 | BA61: =AC61-AVERAGE(AC$32:AC$61)+Sheet2!D$15 -> 7.0925775 | BB61: =AD61-AVERAGE(AD$32:AD$61)+Sheet2!E$15 -> 18.591385 | BC61: =AE61-AVERAGE(AE$32:AE$61)+Sheet2!F$15 -> 19.130606 | BD61: =AF61-AVERAGE(AF$32:AF$61)+Sheet2!G$15 -> 22.44262 | BE61: =AG61-AVERAGE(AG$32:AG$61)+Sheet2!H$15 -> 30.396866 | BF61: =AH61-AVERAGE(AH$32:AH$61)+Sheet2!I$15 -> 13.327351 | BG61: =AI61-AVERAGE(AI$32:AI$61)+Sheet2!J$15 -> 21.393035 | ... BW61: =AY61-AVERAGE(AY$32:AY$61)+Sheet2!Z$15 -> 8.7198591 | BZ61: =BA61-AVERAGE(AH$32:AH$61)+Sheet2!AB$15 -> 5.7760299 | CA61: =BB61-AVERAGE(AI$32:AI$61)+Sheet2!AC$15 -> 17.130996 | CB61: =BC61-AVERAGE(AJ$32:AJ$61)+Sheet2!AD$15 -> 16.102758 | CC61: =BD61-AVERAGE(AK$32:AK$61)+Sheet2!AE$15 -> 19.780665
B62: 61 | C62: 3 | D62: =RAND() -> 0.54832613 | E62: =RAND() -> 0.5532004 | F62: =RAND() -> 0.29086452 | G62: =RAND() -> 0.13105258 | H62: =RAND() -> 0.52769084 | I62: =RAND() -> 0.73118056 | J62: =RAND() -> 0.30340996 | K62: =RAND() -> 0.21780192 | ... AA62: =RAND() -> 0.35133964 | AB62: =D62*Sheet2!C$18/_xlfn.STDEV.S(D$62:D$91) -> 1.7224578 | AC62: =E62*Sheet2!D$18/_xlfn.STDEV.S(E$62:E$91) -> 1.4960389 | AD62: =F62*Sheet2!E$18/_xlfn.STDEV.S(F$62:F$91) -> 1.189974 | AE62: =G62*Sheet2!F$18/_xlfn.STDEV.S(G$62:G$91) -> 1.6063022 | AF62: =H62*Sheet2!G$18/_xlfn.STDEV.S(H$62:H$91) -> 11.005264 | AG62: =I62*Sheet2!H$18/_xlfn.STDEV.S(I$62:I$91) -> 12.040964 | AH62: =J62*Sheet2!I$18/_xlfn.STDEV.S(J$62:J$91) -> 0.95508115 | AI62: =K62*Sheet2!J$18/_xlfn.STDEV.S(K$62:K$91) -> 1.349362 | ... AY62: =AA62*Sheet2!Z$18/_xlfn.STDEV.S(AA$62:AA$91) -> 1.3054875 | AZ62: =AB62-AVERAGE(AB$62:AB$91)+Sheet2!C$17 -> 5.7694553 | BA62: =AC62-AVERAGE(AC$62:AC$91)+Sheet2!D$17 -> 5.344518 | BB62: =AD62-AVERAGE(AD$62:AD$91)+Sheet2!E$17 -> 26.411621 | BC62: =AE62-AVERAGE(AE$62:AE$91)+Sheet2!F$17 -> -1.0344129 | BD62: =AF62-AVERAGE(AF$62:AF$91)+Sheet2!G$17 -> 33.809826 | BE62: =AG62-AVERAGE(AG$62:AG$91)+Sheet2!H$17 -> 25.257055 | BF62: =AH62-AVERAGE(AH$62:AH$91)+Sheet2!I$17 -> 9.510167 | BG62: =AI62-AVERAGE(AI$62:AI$91)+Sheet2!J$17 -> 23.99145 | ... BW62: =AY62-AVERAGE(AY$62:AY$91)+Sheet2!Z$17 -> 9.0847048 | BZ62: =BA62-AVERAGE(AH$62:AH$91)+Sheet2!AB$17 -> 3.7621603 | CA62: =BB62-AVERAGE(AI$62:AI$91)+Sheet2!AC$17 -> 23.80968 | CB62: =BC62-AVERAGE(AJ$62:AJ$91)+Sheet2!AD$17 -> -4.6635357 | CC62: =BD62-AVERAGE(AK$62:AK$91)+Sheet2!AE$17 -> 29.031566
B63: 62 | C63: 3 | D63: =RAND() -> 0.52465939 | E63: =RAND() -> 0.87478946 | F63: =RAND() -> 0.1086232 | G63: =RAND() -> 0.57692264 | H63: =RAND() -> 0.17663728 | I63: =RAND() -> 0.67080776 | J63: =RAND() -> 0.82323793 | K63: =RAND() -> 0.24837475 | ... AA63: =RAND() -> 0.42302407 | AB63: =D63*Sheet2!C$18/_xlfn.STDEV.S(D$62:D$91) -> 1.6481134 | AC63: =E63*Sheet2!D$18/_xlfn.STDEV.S(E$62:E$91) -> 2.3657232 | AD63: =F63*Sheet2!E$18/_xlfn.STDEV.S(F$62:F$91) -> 0.44439518 | AE63: =G63*Sheet2!F$18/_xlfn.STDEV.S(G$62:G$91) -> 7.0713001 | AF63: =H63*Sheet2!G$18/_xlfn.STDEV.S(H$62:H$91) -> 3.6838615 | AG63: =I63*Sheet2!H$18/_xlfn.STDEV.S(I$62:I$91) -> 11.046755 | AH63: =J63*Sheet2!I$18/_xlfn.STDEV.S(J$62:J$91) -> 2.5914081 | AI63: =K63*Sheet2!J$18/_xlfn.STDEV.S(K$62:K$91) -> 1.5387718 | ... AY63: =AA63*Sheet2!Z$18/_xlfn.STDEV.S(AA$62:AA$91) -> 1.5718484 | AZ63: =AB63-AVERAGE(AB$62:AB$91)+Sheet2!C$17 -> 5.6951109 | BA63: =AC63-AVERAGE(AC$62:AC$91)+Sheet2!D$17 -> 6.2142023 | BB63: =AD63-AVERAGE(AD$62:AD$91)+Sheet2!E$17 -> 25.666042 | BC63: =AE63-AVERAGE(AE$62:AE$91)+Sheet2!F$17 -> 4.4305849 | BD63: =AF63-AVERAGE(AF$62:AF$91)+Sheet2!G$17 -> 26.488423 | BE63: =AG63-AVERAGE(AG$62:AG$91)+Sheet2!H$17 -> 24.262845 | BF63: =AH63-AVERAGE(AH$62:AH$91)+Sheet2!I$17 -> 11.146494 | BG63: =AI63-AVERAGE(AI$62:AI$91)+Sheet2!J$17 -> 24.180859 | ... BW63: =AY63-AVERAGE(AY$62:AY$91)+Sheet2!Z$17 -> 9.3510657 | BZ63: =BA63-AVERAGE(AH$62:AH$91)+Sheet2!AB$17 -> 4.6318446 | CA63: =BB63-AVERAGE(AI$62:AI$91)+Sheet2!AC$17 -> 23.064101 | CB63: =BC63-AVERAGE(AJ$62:AJ$91)+Sheet2!AD$17 -> 0.80146213 | CC63: =BD63-AVERAGE(AK$62:AK$91)+Sheet2!AE$17 -> 21.710163
B64: 63 | C64: 3 | D64: =RAND() -> 0.32561191 | E64: =RAND() -> 0.70002006 | F64: =RAND() -> 0.6840014 | G64: =RAND() -> 0.52356167 | H64: =RAND() -> 0.85612251 | I64: =RAND() -> 0.41032942 | J64: =RAND() -> 0.17777246 | K64: =RAND() -> 0.070542122 | ... AA64: =RAND() -> 0.36303611 | AB64: =D64*Sheet2!C$18/_xlfn.STDEV.S(D$62:D$91) -> 1.0228452 | AC64: =E64*Sheet2!D$18/_xlfn.STDEV.S(E$62:E$91) -> 1.8930883 | AD64: =F64*Sheet2!E$18/_xlfn.STDEV.S(F$62:F$91) -> 2.7983609 | AE64: =G64*Sheet2!F$18/_xlfn.STDEV.S(G$62:G$91) -> 6.4172585 | AF64: =H64*Sheet2!G$18/_xlfn.STDEV.S(H$62:H$91) -> 17.854876 | AG64: =I64*Sheet2!H$18/_xlfn.STDEV.S(I$62:I$91) -> 6.7572391 | AH64: =J64*Sheet2!I$18/_xlfn.STDEV.S(J$62:J$91) -> 0.55959642 | AI64: =K64*Sheet2!J$18/_xlfn.STDEV.S(K$62:K$91) -> 0.43703407 | ... AY64: =AA64*Sheet2!Z$18/_xlfn.STDEV.S(AA$62:AA$91) -> 1.3489486 | AZ64: =AB64-AVERAGE(AB$62:AB$91)+Sheet2!C$17 -> 5.0698427 | BA64: =AC64-AVERAGE(AC$62:AC$91)+Sheet2!D$17 -> 5.7415674 | BB64: =AD64-AVERAGE(AD$62:AD$91)+Sheet2!E$17 -> 28.020008 | BC64: =AE64-AVERAGE(AE$62:AE$91)+Sheet2!F$17 -> 3.7765433 | BD64: =AF64-AVERAGE(AF$62:AF$91)+Sheet2!G$17 -> 40.659437 | BE64: =AG64-AVERAGE(AG$62:AG$91)+Sheet2!H$17 -> 19.973329 | BF64: =AH64-AVERAGE(AH$62:AH$91)+Sheet2!I$17 -> 9.1146823 | BG64: =AI64-AVERAGE(AI$62:AI$91)+Sheet2!J$17 -> 23.079122 | ... BW64: =AY64-AVERAGE(AY$62:AY$91)+Sheet2!Z$17 -> 9.1281659 | BZ64: =BA64-AVERAGE(AH$62:AH$91)+Sheet2!AB$17 -> 4.1592097 | CA64: =BB64-AVERAGE(AI$62:AI$91)+Sheet2!AC$17 -> 25.418067 | CB64: =BC64-AVERAGE(AJ$62:AJ$91)+Sheet2!AD$17 -> 0.14742053 | CC64: =BD64-AVERAGE(AK$62:AK$91)+Sheet2!AE$17 -> 35.881178
B65: 64 | C65: 3 | D65: =RAND() -> 0.96807803 | E65: =RAND() -> 0.54694858 | F65: =RAND() -> 0.99606139 | G65: =RAND() -> 0.90422065 | H65: =RAND() -> 0.73706473 | I65: =RAND() -> 0.55161129 | J65: =RAND() -> 0.93509082 | K65: =RAND() -> 0.63937478 | ... AA65: =RAND() -> 0.54975806 | AB65: =D65*Sheet2!C$18/_xlfn.STDEV.S(D$62:D$91) -> 3.041025 | AC65: =E65*Sheet2!D$18/_xlfn.STDEV.S(E$62:E$91) -> 1.4791318 | AD65: =F65*Sheet2!E$18/_xlfn.STDEV.S(F$62:F$91) -> 4.075049 | AE65: =G65*Sheet2!F$18/_xlfn.STDEV.S(G$62:G$91) -> 11.082969 | AF65: =H65*Sheet2!G$18/_xlfn.STDEV.S(H$62:H$91) -> 15.371864 | AG65: =I65*Sheet2!H$18/_xlfn.STDEV.S(I$62:I$91) -> 9.0838463 | AH65: =J65*Sheet2!I$18/_xlfn.STDEV.S(J$62:J$91) -> 2.9435013 | AI65: =K65*Sheet2!J$18/_xlfn.STDEV.S(K$62:K$91) -> 3.961159 | ... AY65: =AA65*Sheet2!Z$18/_xlfn.STDEV.S(AA$62:AA$91) -> 2.0427593 | AZ65: =AB65-AVERAGE(AB$62:AB$91)+Sheet2!C$17 -> 7.0880226 | BA65: =AC65-AVERAGE(AC$62:AC$91)+Sheet2!D$17 -> 5.3276109 | BB65: =AD65-AVERAGE(AD$62:AD$91)+Sheet2!E$17 -> 29.296696 | BC65: =AE65-AVERAGE(AE$62:AE$91)+Sheet2!F$17 -> 8.4422536 | BD65: =AF65-AVERAGE(AF$62:AF$91)+Sheet2!G$17 -> 38.176426 | BE65: =AG65-AVERAGE(AG$62:AG$91)+Sheet2!H$17 -> 22.299937 | BF65: =AH65-AVERAGE(AH$62:AH$91)+Sheet2!I$17 -> 11.498587 | BG65: =AI65-AVERAGE(AI$62:AI$91)+Sheet2!J$17 -> 26.603246 | ... BW65: =AY65-AVERAGE(AY$62:AY$91)+Sheet2!Z$17 -> 9.8219766 | BZ65: =BA65-AVERAGE(AH$62:AH$91)+Sheet2!AB$17 -> 3.7452533 | CA65: =BB65-AVERAGE(AI$62:AI$91)+Sheet2!AC$17 -> 26.694755 | CB65: =BC65-AVERAGE(AJ$62:AJ$91)+Sheet2!AD$17 -> 4.8131308 | CC65: =BD65-AVERAGE(AK$62:AK$91)+Sheet2!AE$17 -> 33.398166
B66: 65 | C66: 3 | D66: =RAND() -> 0.029999646 | E66: =RAND() -> 0.77266627 | F66: =RAND() -> 0.96301345 | G66: =RAND() -> 0.17840325 | H66: =RAND() -> 0.92130892 | I66: =RAND() -> 0.53039301 | J66: =RAND() -> 0.34603108 | K66: =RAND() -> 0.011735509 | ... AA66: =RAND() -> 0.82590643 | AB66: =D66*Sheet2!C$18/_xlfn.STDEV.S(D$62:D$91) -> 0.094237935 | AC66: =E66*Sheet2!D$18/_xlfn.STDEV.S(E$62:E$91) -> 2.0895479 | AD66: =F66*Sheet2!E$18/_xlfn.STDEV.S(F$62:F$91) -> 3.9398445 | AE66: =G66*Sheet2!F$18/_xlfn.STDEV.S(G$62:G$91) -> 2.186676 | AF66: =H66*Sheet2!G$18/_xlfn.STDEV.S(H$62:H$91) -> 19.214372 | AG66: =I66*Sheet2!H$18/_xlfn.STDEV.S(I$62:I$91) -> 8.7344272 | AH66: =J66*Sheet2!I$18/_xlfn.STDEV.S(J$62:J$91) -> 1.0892449 | AI66: =K66*Sheet2!J$18/_xlfn.STDEV.S(K$62:K$91) -> 0.072705741 | ... AY66: =AA66*Sheet2!Z$18/_xlfn.STDEV.S(AA$62:AA$91) -> 3.0688554 | AZ66: =AB66-AVERAGE(AB$62:AB$91)+Sheet2!C$17 -> 4.1412354 | BA66: =AC66-AVERAGE(AC$62:AC$91)+Sheet2!D$17 -> 5.9380271 | BB66: =AD66-AVERAGE(AD$62:AD$91)+Sheet2!E$17 -> 29.161492 | BC66: =AE66-AVERAGE(AE$62:AE$91)+Sheet2!F$17 -> -0.4540391 | BD66: =AF66-AVERAGE(AF$62:AF$91)+Sheet2!G$17 -> 42.018933 | BE66: =AG66-AVERAGE(AG$62:AG$91)+Sheet2!H$17 -> 21.950517 | BF66: =AH66-AVERAGE(AH$62:AH$91)+Sheet2!I$17 -> 9.6443308 | BG66: =AI66-AVERAGE(AI$62:AI$91)+Sheet2!J$17 -> 22.714793 | ... BW66: =AY66-AVERAGE(AY$62:AY$91)+Sheet2!Z$17 -> 10.848073 | BZ66: =BA66-AVERAGE(AH$62:AH$91)+Sheet2!AB$17 -> 4.3556694 | CA66: =BB66-AVERAGE(AI$62:AI$91)+Sheet2!AC$17 -> 26.559551 | CB66: =BC66-AVERAGE(AJ$62:AJ$91)+Sheet2!AD$17 -> -4.0831619 | CC66: =BD66-AVERAGE(AK$62:AK$91)+Sheet2!AE$17 -> 37.240674
B67: 66 | C67: 3 | D67: =RAND() -> 0.6406812 | E67: =RAND() -> 0.39456386 | F67: =RAND() -> 0.26516905 | G67: =RAND() -> 0.72945432 | H67: =RAND() -> 0.95325871 | I67: =RAND() -> 0.3330743 | J67: =RAND() -> 0.6093542 | K67: =RAND() -> 0.33655884 | ... AA67: =RAND() -> 0.31186169 | AB67: =D67*Sheet2!C$18/_xlfn.STDEV.S(D$62:D$91) -> 2.0125729 | AC67: =E67*Sheet2!D$18/_xlfn.STDEV.S(E$62:E$91) -> 1.0670326 | AD67: =F67*Sheet2!E$18/_xlfn.STDEV.S(F$62:F$91) -> 1.0848497 | AE67: =G67*Sheet2!F$18/_xlfn.STDEV.S(G$62:G$91) -> 8.9408702 | AF67: =H67*Sheet2!G$18/_xlfn.STDEV.S(H$62:H$91) -> 19.880701 | AG67: =I67*Sheet2!H$18/_xlfn.STDEV.S(I$62:I$91) -> 5.4850142 | AH67: =J67*Sheet2!I$18/_xlfn.STDEV.S(J$62:J$91) -> 1.9181398 | AI67: =K67*Sheet2!J$18/_xlfn.STDEV.S(K$62:K$91) -> 2.0851043 | ... AY67: =AA67*Sheet2!Z$18/_xlfn.STDEV.S(AA$62:AA$91) -> 1.1587977 | AZ67: =AB67-AVERAGE(AB$62:AB$91)+Sheet2!C$17 -> 6.0595704 | BA67: =AC67-AVERAGE(AC$62:AC$91)+Sheet2!D$17 -> 4.9155117 | BB67: =AD67-AVERAGE(AD$62:AD$91)+Sheet2!E$17 -> 26.306497 | BC67: =AE67-AVERAGE(AE$62:AE$91)+Sheet2!F$17 -> 6.3001551 | BD67: =AF67-AVERAGE(AF$62:AF$91)+Sheet2!G$17 -> 42.685263 | BE67: =AG67-AVERAGE(AG$62:AG$91)+Sheet2!H$17 -> 18.701104 | BF67: =AH67-AVERAGE(AH$62:AH$91)+Sheet2!I$17 -> 10.473226 | BG67: =AI67-AVERAGE(AI$62:AI$91)+Sheet2!J$17 -> 24.727192 | ... BW67: =AY67-AVERAGE(AY$62:AY$91)+Sheet2!Z$17 -> 8.938015 | BZ67: =BA67-AVERAGE(AH$62:AH$91)+Sheet2!AB$17 -> 3.333154 | CA67: =BB67-AVERAGE(AI$62:AI$91)+Sheet2!AC$17 -> 23.704556 | CB67: =BC67-AVERAGE(AJ$62:AJ$91)+Sheet2!AD$17 -> 2.6710323 | CC67: =BD67-AVERAGE(AK$62:AK$91)+Sheet2!AE$17 -> 37.907003
B68: 67 | C68: 3 | D68: =RAND() -> 0.75045913 | E68: =RAND() -> 0.89375493 | F68: =RAND() -> 0.17317881 | G68: =RAND() -> 0.84994861 | H68: =RAND() -> 0.88735019 | I68: =RAND() -> 0.23741702 | J68: =RAND() -> 0.25298239 | K68: =RAND() -> 0.043970987 | ... AA68: =RAND() -> 0.3263045 | AB68: =D68*Sheet2!C$18/_xlfn.STDEV.S(D$62:D$91) -> 2.3574185 | AC68: =E68*Sheet2!D$18/_xlfn.STDEV.S(E$62:E$91) -> 2.4170121 | AD68: =F68*Sheet2!E$18/_xlfn.STDEV.S(F$62:F$91) -> 0.70850264 | AE68: =G68*Sheet2!F$18/_xlfn.STDEV.S(G$62:G$91) -> 10.41776 | AF68: =H68*Sheet2!G$18/_xlfn.STDEV.S(H$62:H$91) -> 18.506145 | AG68: =I68*Sheet2!H$18/_xlfn.STDEV.S(I$62:I$91) -> 3.9097455 | AH68: =J68*Sheet2!I$18/_xlfn.STDEV.S(J$62:J$91) -> 0.79634405 | AI68: =K68*Sheet2!J$18/_xlfn.STDEV.S(K$62:K$91) -> 0.27241624 | ... AY68: =AA68*Sheet2!Z$18/_xlfn.STDEV.S(AA$62:AA$91) -> 1.2124634 | AZ68: =AB68-AVERAGE(AB$62:AB$91)+Sheet2!C$17 -> 6.404416 | BA68: =AC68-AVERAGE(AC$62:AC$91)+Sheet2!D$17 -> 6.2654913 | BB68: =AD68-AVERAGE(AD$62:AD$91)+Sheet2!E$17 -> 25.93015 | BC68: =AE68-AVERAGE(AE$62:AE$91)+Sheet2!F$17 -> 7.777045 | BD68: =AF68-AVERAGE(AF$62:AF$91)+Sheet2!G$17 -> 41.310707 | BE68: =AG68-AVERAGE(AG$62:AG$91)+Sheet2!H$17 -> 17.125836 | BF68: =AH68-AVERAGE(AH$62:AH$91)+Sheet2!I$17 -> 9.3514299 | BG68: =AI68-AVERAGE(AI$62:AI$91)+Sheet2!J$17 -> 22.914504 | ... BW68: =AY68-AVERAGE(AY$62:AY$91)+Sheet2!Z$17 -> 8.9916807 | BZ68: =BA68-AVERAGE(AH$62:AH$91)+Sheet2!AB$17 -> 4.6831336 | CA68: =BB68-AVERAGE(AI$62:AI$91)+Sheet2!AC$17 -> 23.328209 | CB68: =BC68-AVERAGE(AJ$62:AJ$91)+Sheet2!AD$17 -> 4.1479222 | CC68: =BD68-AVERAGE(AK$62:AK$91)+Sheet2!AE$17 -> 36.532447
B69: 68 | C69: 3 | D69: =RAND() -> 0.69750553 | E69: =RAND() -> 0.45175143 | F69: =RAND() -> 0.94591865 | G69: =RAND() -> 0.12651541 | H69: =RAND() -> 0.34812325 | I69: =RAND() -> 0.51016951 | J69: =RAND() -> 0.56518913 | K69: =RAND() -> 0.14739047 | ... AA69: =RAND() -> 0.4898341 | AB69: =D69*Sheet2!C$18/_xlfn.STDEV.S(D$62:D$91) -> 2.1910752 | AC69: =E69*Sheet2!D$18/_xlfn.STDEV.S(E$62:E$91) -> 1.2216869 | AD69: =F69*Sheet2!E$18/_xlfn.STDEV.S(F$62:F$91) -> 3.8699069 | AE69: =G69*Sheet2!F$18/_xlfn.STDEV.S(G$62:G$91) -> 1.5506905 | AF69: =H69*Sheet2!G$18/_xlfn.STDEV.S(H$62:H$91) -> 7.2602896 | AG69: =I69*Sheet2!H$18/_xlfn.STDEV.S(I$62:I$91) -> 8.4013898 | AH69: =J69*Sheet2!I$18/_xlfn.STDEV.S(J$62:J$91) -> 1.7791159 | AI69: =K69*Sheet2!J$18/_xlfn.STDEV.S(K$62:K$91) -> 0.9131375 | ... AY69: =AA69*Sheet2!Z$18/_xlfn.STDEV.S(AA$62:AA$91) -> 1.8200973 | AZ69: =AB69-AVERAGE(AB$62:AB$91)+Sheet2!C$17 -> 6.2380727 | BA69: =AC69-AVERAGE(AC$62:AC$91)+Sheet2!D$17 -> 5.070166 | BB69: =AD69-AVERAGE(AD$62:AD$91)+Sheet2!E$17 -> 29.091554 | BC69: =AE69-AVERAGE(AE$62:AE$91)+Sheet2!F$17 -> -1.0900247 | BD69: =AF69-AVERAGE(AF$62:AF$91)+Sheet2!G$17 -> 30.064851 | BE69: =AG69-AVERAGE(AG$62:AG$91)+Sheet2!H$17 -> 21.61748 | BF69: =AH69-AVERAGE(AH$62:AH$91)+Sheet2!I$17 -> 10.334202 | BG69: =AI69-AVERAGE(AI$62:AI$91)+Sheet2!J$17 -> 23.555225 | ... BW69: =AY69-AVERAGE(AY$62:AY$91)+Sheet2!Z$17 -> 9.5993146 | BZ69: =BA69-AVERAGE(AH$62:AH$91)+Sheet2!AB$17 -> 3.4878084 | CA69: =BB69-AVERAGE(AI$62:AI$91)+Sheet2!AC$17 -> 26.489613 | CB69: =BC69-AVERAGE(AJ$62:AJ$91)+Sheet2!AD$17 -> -4.7191475 | CC69: =BD69-AVERAGE(AK$62:AK$91)+Sheet2!AE$17 -> 25.286591
B70: 69 | C70: 3 | D70: =RAND() -> 0.32098606 | E70: =RAND() -> 0.14887735 | F70: =RAND() -> 0.89128269 | G70: =RAND() -> 0.32260241 | H70: =RAND() -> 0.045503662 | I70: =RAND() -> 0.75475787 | J70: =RAND() -> 0.85949798 | K70: =RAND() -> 0.43543259 | ... AA70: =RAND() -> 0.94454592 | AB70: =D70*Sheet2!C$18/_xlfn.STDEV.S(D$62:D$91) -> 1.008314 | AC70: =E70*Sheet2!D$18/_xlfn.STDEV.S(E$62:E$91) -> 0.40261413 | AD70: =F70*Sheet2!E$18/_xlfn.STDEV.S(F$62:F$91) -> 3.6463823 | AE70: =G70*Sheet2!F$18/_xlfn.STDEV.S(G$62:G$91) -> 3.954115 | AF70: =H70*Sheet2!G$18/_xlfn.STDEV.S(H$62:H$91) -> 0.9490023 | AG70: =I70*Sheet2!H$18/_xlfn.STDEV.S(I$62:I$91) -> 12.429232 | AH70: =J70*Sheet2!I$18/_xlfn.STDEV.S(J$62:J$91) -> 2.7055484 | AI70: =K70*Sheet2!J$18/_xlfn.STDEV.S(K$62:K$91) -> 2.697663 | ... AY70: =AA70*Sheet2!Z$18/_xlfn.STDEV.S(AA$62:AA$91) -> 3.5096892 | AZ70: =AB70-AVERAGE(AB$62:AB$91)+Sheet2!C$17 -> 5.0553115 | BA70: =AC70-AVERAGE(AC$62:AC$91)+Sheet2!D$17 -> 4.2510933 | BB70: =AD70-AVERAGE(AD$62:AD$91)+Sheet2!E$17 -> 28.86803 | BC70: =AE70-AVERAGE(AE$62:AE$91)+Sheet2!F$17 -> 1.3133998 | BD70: =AF70-AVERAGE(AF$62:AF$91)+Sheet2!G$17 -> 23.753564 | BE70: =AG70-AVERAGE(AG$62:AG$91)+Sheet2!H$17 -> 25.645322 | BF70: =AH70-AVERAGE(AH$62:AH$91)+Sheet2!I$17 -> 11.260634 | BG70: =AI70-AVERAGE(AI$62:AI$91)+Sheet2!J$17 -> 25.339751 | ... BW70: =AY70-AVERAGE(AY$62:AY$91)+Sheet2!Z$17 -> 11.288907 | BZ70: =BA70-AVERAGE(AH$62:AH$91)+Sheet2!AB$17 -> 2.6687356 | CA70: =BB70-AVERAGE(AI$62:AI$91)+Sheet2!AC$17 -> 26.266089 | CB70: =BC70-AVERAGE(AJ$62:AJ$91)+Sheet2!AD$17 -> -2.315723 | CC70: =BD70-AVERAGE(AK$62:AK$91)+Sheet2!AE$17 -> 18.975304
